2021-02-17 18:56:08,153:INFO:PyCaret Supervised Module
2021-02-17 18:56:08,153:INFO:ML Usecase: classification
2021-02-17 18:56:08,153:INFO:version 2.2.2
2021-02-17 18:56:08,153:INFO:Initializing setup()
2021-02-17 18:56:08,153:INFO:setup(target=No-show, ml_usecase=classification, available_plots={'parameter': 'Hyperparameters', 'auc': 'AUC', 'confusion_matrix': 'Confusion Matrix', 'threshold': 'Threshold', 'pr': 'Precision Recall', 'error': 'Prediction Error', 'class_report': 'Class Report', 'rfe': 'Feature Selection', 'learning': 'Learning Curve', 'manifold': 'Manifold Learning', 'calibration': 'Calibration Curve', 'vc': 'Validation Curve', 'dimension': 'Dimensions', 'feature': 'Feature Importance', 'feature_all': 'Feature Importance (All)', 'boundary': 'Decision Boundary', 'lift': 'Lift Chart', 'gain': 'Gain Chart', 'tree': 'Decision Tree'}, train_size=0.7, test_data=None, preprocess=True, imputation_type=simple, iterative_imputation_iters=5, categorical_features=None, categorical_imputation=constant, categorical_iterative_imputer=lightgbm, ordinal_features=None, high_cardinality_features=None, high_cardinality_method=frequency, numeric_features=None, numeric_imputation=mean, numeric_iterative_imputer=lightgbm, date_features=None, ignore_features=None, normalize=False, normalize_method=zscore, transformation=False, transformation_method=yeo-johnson, handle_unknown_categorical=True, unknown_categorical_method=least_frequent, pca=False, pca_method=linear, pca_components=None, ignore_low_variance=False, combine_rare_levels=False, rare_level_threshold=0.1, bin_numeric_features=None, remove_outliers=False, outliers_threshold=0.05, remove_multicollinearity=False, multicollinearity_threshold=0.9, remove_perfect_collinearity=True, create_clusters=False, cluster_iter=20, polynomial_features=False, polynomial_degree=2, trigonometry_features=False, polynomial_threshold=0.1, group_features=None, group_names=None, feature_selection=False, feature_selection_threshold=0.8, feature_selection_method=classic, feature_interaction=False, feature_ratio=False, interaction_threshold=0.01, fix_imbalance=False, fix_imbalance_method=None, transform_target=False, transform_target_method=box-cox, data_split_shuffle=True, data_split_stratify=False, fold_strategy=stratifiedkfold, fold=10, fold_shuffle=False, fold_groups=None, n_jobs=-1, use_gpu=False, custom_pipeline=None, html=True, session_id=None, log_experiment=False, experiment_name=None, log_plots=False, log_profile=False, log_data=False, silent=False, verbose=True, profile=False, profile_kwargs=None, display=None)
2021-02-17 18:56:08,153:INFO:Checking environment
2021-02-17 18:56:08,153:INFO:python_version: 3.8.5
2021-02-17 18:56:08,159:INFO:python_build: ('default', 'Sep  3 2020 21:29:08')
2021-02-17 18:56:08,159:INFO:machine: AMD64
2021-02-17 18:56:08,160:INFO:platform: Windows-10-10.0.18362-SP0
2021-02-17 18:56:08,160:INFO:Memory: svmem(total=8416362496, available=4103573504, percent=51.2, used=4312788992, free=4103573504)
2021-02-17 18:56:08,161:INFO:Physical Core: 2
2021-02-17 18:56:08,161:INFO:Logical Core: 4
2021-02-17 18:56:08,162:INFO:Checking libraries
2021-02-17 18:56:08,162:INFO:pd==1.1.3
2021-02-17 18:56:08,162:INFO:numpy==1.19.2
2021-02-17 18:56:08,163:INFO:sklearn==0.23.2
2021-02-17 18:56:08,751:INFO:xgboost==1.3.0
2021-02-17 18:56:08,751:INFO:lightgbm==3.1.1
2021-02-17 18:56:08,985:INFO:catboost==0.24.3
2021-02-17 18:56:12,022:INFO:mlflow==1.12.1
2021-02-17 18:56:12,023:INFO:Checking Exceptions
2021-02-17 18:56:12,024:INFO:Declaring global variables
2021-02-17 18:56:12,024:INFO:USI: ba70
2021-02-17 18:56:12,024:INFO:pycaret_globals: {'data_before_preprocess', 'log_plots_param', '_ml_usecase', 'X', 'USI', 'master_model_container', 'pycaret_globals', 'y_train', 'imputation_regressor', 'create_model_container', 'fix_imbalance_method_param', 'X_train', 'X_test', 'fold_param', 'target_param', 'display_container', '_all_models_internal', '_internal_pipeline', 'fix_imbalance_param', '_available_plots', 'imputation_classifier', 'fold_generator', '_all_models', 'y_test', 'seed', 'logging_param', 'y', 'iterative_imputation_iters_param', 'stratify_param', 'fold_groups_param', 'exp_name_log', 'transform_target_param', 'transform_target_method_param', 'gpu_param', 'html_param', '_all_metrics', 'fold_shuffle_param', '_gpu_n_jobs_param', 'n_jobs_param', 'prep_pipe', 'experiment__'}
2021-02-17 18:56:12,024:INFO:Preparing display monitor
2021-02-17 18:56:12,025:INFO:Preparing display monitor
2021-02-17 18:56:12,075:INFO:Importing libraries
2021-02-17 18:56:12,075:INFO:Copying data for preprocessing
2021-02-17 18:56:12,227:INFO:Declaring preprocessing parameters
2021-02-17 18:56:12,445:INFO:Creating preprocessing pipeline
2021-02-17 18:56:14,840:INFO:Preprocessing pipeline created successfully
2021-02-17 18:56:14,844:ERROR:(Process Exit): setup has been interupted with user command 'quit'. setup must rerun.
2021-02-17 18:56:14,844:INFO:Creating global containers
2021-02-17 18:56:14,847:INFO:Internal pipeline: Pipeline(memory=None, steps=[('empty_step', 'passthrough')], verbose=False)
2021-02-17 18:59:59,576:INFO:PyCaret Supervised Module
2021-02-17 18:59:59,576:INFO:ML Usecase: classification
2021-02-17 18:59:59,576:INFO:version 2.2.2
2021-02-17 18:59:59,576:INFO:Initializing setup()
2021-02-17 18:59:59,576:INFO:setup(target=No-show, ml_usecase=classification, available_plots={'parameter': 'Hyperparameters', 'auc': 'AUC', 'confusion_matrix': 'Confusion Matrix', 'threshold': 'Threshold', 'pr': 'Precision Recall', 'error': 'Prediction Error', 'class_report': 'Class Report', 'rfe': 'Feature Selection', 'learning': 'Learning Curve', 'manifold': 'Manifold Learning', 'calibration': 'Calibration Curve', 'vc': 'Validation Curve', 'dimension': 'Dimensions', 'feature': 'Feature Importance', 'feature_all': 'Feature Importance (All)', 'boundary': 'Decision Boundary', 'lift': 'Lift Chart', 'gain': 'Gain Chart', 'tree': 'Decision Tree'}, train_size=0.7, test_data=None, preprocess=True, imputation_type=simple, iterative_imputation_iters=5, categorical_features=None, categorical_imputation=constant, categorical_iterative_imputer=lightgbm, ordinal_features=None, high_cardinality_features=None, high_cardinality_method=frequency, numeric_features=None, numeric_imputation=mean, numeric_iterative_imputer=lightgbm, date_features=None, ignore_features=None, normalize=False, normalize_method=zscore, transformation=False, transformation_method=yeo-johnson, handle_unknown_categorical=True, unknown_categorical_method=least_frequent, pca=False, pca_method=linear, pca_components=None, ignore_low_variance=False, combine_rare_levels=False, rare_level_threshold=0.1, bin_numeric_features=None, remove_outliers=False, outliers_threshold=0.05, remove_multicollinearity=False, multicollinearity_threshold=0.9, remove_perfect_collinearity=True, create_clusters=False, cluster_iter=20, polynomial_features=False, polynomial_degree=2, trigonometry_features=False, polynomial_threshold=0.1, group_features=None, group_names=None, feature_selection=False, feature_selection_threshold=0.8, feature_selection_method=classic, feature_interaction=False, feature_ratio=False, interaction_threshold=0.01, fix_imbalance=False, fix_imbalance_method=None, transform_target=False, transform_target_method=box-cox, data_split_shuffle=True, data_split_stratify=False, fold_strategy=stratifiedkfold, fold=10, fold_shuffle=False, fold_groups=None, n_jobs=-1, use_gpu=False, custom_pipeline=None, html=True, session_id=None, log_experiment=False, experiment_name=None, log_plots=False, log_profile=False, log_data=False, silent=False, verbose=True, profile=False, profile_kwargs=None, display=None)
2021-02-17 18:59:59,576:INFO:Checking environment
2021-02-17 18:59:59,576:INFO:python_version: 3.8.5
2021-02-17 18:59:59,576:INFO:python_build: ('default', 'Sep  3 2020 21:29:08')
2021-02-17 18:59:59,576:INFO:machine: AMD64
2021-02-17 18:59:59,577:INFO:platform: Windows-10-10.0.18362-SP0
2021-02-17 18:59:59,577:INFO:Memory: svmem(total=8416362496, available=2930397184, percent=65.2, used=5485965312, free=2930397184)
2021-02-17 18:59:59,577:INFO:Physical Core: 2
2021-02-17 18:59:59,578:INFO:Logical Core: 4
2021-02-17 18:59:59,579:INFO:Checking libraries
2021-02-17 18:59:59,579:INFO:pd==1.1.3
2021-02-17 18:59:59,580:INFO:numpy==1.19.2
2021-02-17 18:59:59,580:INFO:sklearn==0.23.2
2021-02-17 18:59:59,580:INFO:xgboost==1.3.0
2021-02-17 18:59:59,581:INFO:lightgbm==3.1.1
2021-02-17 18:59:59,581:INFO:catboost==0.24.3
2021-02-17 18:59:59,581:INFO:mlflow==1.12.1
2021-02-17 18:59:59,582:INFO:Checking Exceptions
2021-02-17 18:59:59,582:INFO:Declaring global variables
2021-02-17 18:59:59,582:INFO:USI: 65fb
2021-02-17 18:59:59,582:INFO:pycaret_globals: {'data_before_preprocess', 'log_plots_param', '_ml_usecase', 'X', 'USI', 'master_model_container', 'pycaret_globals', 'y_train', 'imputation_regressor', 'create_model_container', 'fix_imbalance_method_param', 'X_train', 'X_test', 'fold_param', 'target_param', 'display_container', '_all_models_internal', '_internal_pipeline', 'fix_imbalance_param', '_available_plots', 'imputation_classifier', 'fold_generator', '_all_models', 'y_test', 'seed', 'logging_param', 'y', 'iterative_imputation_iters_param', 'stratify_param', 'fold_groups_param', 'exp_name_log', 'transform_target_param', 'transform_target_method_param', 'gpu_param', 'html_param', '_all_metrics', 'fold_shuffle_param', '_gpu_n_jobs_param', 'n_jobs_param', 'prep_pipe', 'experiment__'}
2021-02-17 18:59:59,582:INFO:Preparing display monitor
2021-02-17 18:59:59,582:INFO:Preparing display monitor
2021-02-17 18:59:59,620:INFO:Importing libraries
2021-02-17 18:59:59,621:INFO:Copying data for preprocessing
2021-02-17 18:59:59,776:INFO:Declaring preprocessing parameters
2021-02-17 19:00:00,000:INFO:Creating preprocessing pipeline
2021-02-17 19:00:02,680:INFO:Preprocessing pipeline created successfully
2021-02-17 19:00:02,680:ERROR:(Process Exit): setup has been interupted with user command 'quit'. setup must rerun.
2021-02-17 19:00:02,680:INFO:Creating global containers
2021-02-17 19:00:02,681:INFO:Internal pipeline: Pipeline(memory=None, steps=[('empty_step', 'passthrough')], verbose=False)
2021-02-17 19:01:41,098:INFO:Creating grid variables
2021-02-17 19:01:41,193:INFO:create_model_container: 0
2021-02-17 19:01:41,194:INFO:master_model_container: 0
2021-02-17 19:01:41,194:INFO:display_container: 0
2021-02-17 19:01:41,198:INFO:Pipeline(memory=None,
         steps=[('dtypes',
                 DataTypes_Auto_infer(categorical_features=[],
                                      display_types=True, features_todrop=[],
                                      id_columns=[], ml_usecase='regression',
                                      numerical_features=[], target='No-show',
                                      time_features=[])),
                ('imputer',
                 Simple_Imputer(categorical_strategy='not_available',
                                fill_value_categorical=None,
                                fill_value_numerical=None,
                                numeric_strategy...
                ('scaling', 'passthrough'), ('P_transform', 'passthrough'),
                ('binn', 'passthrough'), ('rem_outliers', 'passthrough'),
                ('cluster_all', 'passthrough'),
                ('dummy', Dummify(target='No-show')),
                ('fix_perfect', Remove_100(target='No-show')),
                ('clean_names', Clean_Colum_Names()),
                ('feature_select', 'passthrough'), ('fix_multi', 'passthrough'),
                ('dfs', 'passthrough'), ('pca', 'passthrough')],
         verbose=False)
2021-02-17 19:01:41,198:INFO:setup() succesfully completed......................................
2021-02-18 14:26:04,106:INFO:PyCaret Supervised Module
2021-02-18 14:26:04,107:INFO:ML Usecase: classification
2021-02-18 14:26:04,107:INFO:version 2.2.2
2021-02-18 14:26:04,108:INFO:Initializing setup()
2021-02-18 14:26:04,108:INFO:setup(target=No-show, ml_usecase=classification, available_plots={'parameter': 'Hyperparameters', 'auc': 'AUC', 'confusion_matrix': 'Confusion Matrix', 'threshold': 'Threshold', 'pr': 'Precision Recall', 'error': 'Prediction Error', 'class_report': 'Class Report', 'rfe': 'Feature Selection', 'learning': 'Learning Curve', 'manifold': 'Manifold Learning', 'calibration': 'Calibration Curve', 'vc': 'Validation Curve', 'dimension': 'Dimensions', 'feature': 'Feature Importance', 'feature_all': 'Feature Importance (All)', 'boundary': 'Decision Boundary', 'lift': 'Lift Chart', 'gain': 'Gain Chart', 'tree': 'Decision Tree'}, train_size=0.7, test_data=None, preprocess=True, imputation_type=simple, iterative_imputation_iters=5, categorical_features=None, categorical_imputation=constant, categorical_iterative_imputer=lightgbm, ordinal_features=None, high_cardinality_features=None, high_cardinality_method=frequency, numeric_features=None, numeric_imputation=mean, numeric_iterative_imputer=lightgbm, date_features=None, ignore_features=None, normalize=False, normalize_method=zscore, transformation=False, transformation_method=yeo-johnson, handle_unknown_categorical=True, unknown_categorical_method=least_frequent, pca=False, pca_method=linear, pca_components=None, ignore_low_variance=False, combine_rare_levels=False, rare_level_threshold=0.1, bin_numeric_features=None, remove_outliers=False, outliers_threshold=0.05, remove_multicollinearity=False, multicollinearity_threshold=0.9, remove_perfect_collinearity=True, create_clusters=False, cluster_iter=20, polynomial_features=False, polynomial_degree=2, trigonometry_features=False, polynomial_threshold=0.1, group_features=None, group_names=None, feature_selection=False, feature_selection_threshold=0.8, feature_selection_method=classic, feature_interaction=False, feature_ratio=False, interaction_threshold=0.01, fix_imbalance=False, fix_imbalance_method=None, transform_target=False, transform_target_method=box-cox, data_split_shuffle=True, data_split_stratify=False, fold_strategy=stratifiedkfold, fold=10, fold_shuffle=False, fold_groups=None, n_jobs=-1, use_gpu=False, custom_pipeline=None, html=True, session_id=None, log_experiment=False, experiment_name=None, log_plots=False, log_profile=False, log_data=False, silent=False, verbose=True, profile=False, profile_kwargs=None, display=None)
2021-02-18 14:26:04,108:INFO:Checking environment
2021-02-18 14:26:04,108:INFO:python_version: 3.8.5
2021-02-18 14:26:04,108:INFO:python_build: ('default', 'Sep  3 2020 21:29:08')
2021-02-18 14:26:04,108:INFO:machine: AMD64
2021-02-18 14:26:04,109:INFO:platform: Windows-10-10.0.18362-SP0
2021-02-18 14:26:04,109:INFO:Memory: svmem(total=8416362496, available=3251707904, percent=61.4, used=5164654592, free=3251707904)
2021-02-18 14:26:04,109:INFO:Physical Core: 2
2021-02-18 14:26:04,109:INFO:Logical Core: 4
2021-02-18 14:26:04,109:INFO:Checking libraries
2021-02-18 14:26:04,109:INFO:pd==1.1.3
2021-02-18 14:26:04,110:INFO:numpy==1.19.2
2021-02-18 14:26:04,110:INFO:sklearn==0.23.2
2021-02-18 14:26:04,462:INFO:xgboost==1.3.0
2021-02-18 14:26:04,463:INFO:lightgbm==3.1.1
2021-02-18 14:26:04,688:INFO:catboost==0.24.3
2021-02-18 14:26:06,398:INFO:mlflow==1.12.1
2021-02-18 14:26:06,399:INFO:Checking Exceptions
2021-02-18 14:26:06,399:INFO:Declaring global variables
2021-02-18 14:26:06,400:INFO:USI: 5662
2021-02-18 14:26:06,400:INFO:pycaret_globals: {'pycaret_globals', 'fold_groups_param', 'create_model_container', 'seed', 'imputation_classifier', 'logging_param', 'stratify_param', 'fold_param', 'transform_target_param', 'master_model_container', 'data_before_preprocess', '_all_models', 'X_test', 'display_container', '_gpu_n_jobs_param', 'y', 'experiment__', 'transform_target_method_param', 'prep_pipe', 'gpu_param', 'USI', 'log_plots_param', 'target_param', 'X_train', '_all_metrics', 'iterative_imputation_iters_param', 'fix_imbalance_method_param', '_available_plots', '_all_models_internal', 'fix_imbalance_param', 'n_jobs_param', 'html_param', '_ml_usecase', 'exp_name_log', 'y_test', 'fold_shuffle_param', 'X', '_internal_pipeline', 'fold_generator', 'y_train', 'imputation_regressor'}
2021-02-18 14:26:06,400:INFO:Preparing display monitor
2021-02-18 14:26:06,400:INFO:Preparing display monitor
2021-02-18 14:26:06,430:INFO:Importing libraries
2021-02-18 14:26:06,430:INFO:Copying data for preprocessing
2021-02-18 14:26:06,532:INFO:Declaring preprocessing parameters
2021-02-18 14:26:06,688:INFO:Creating preprocessing pipeline
2021-02-18 14:26:08,056:INFO:Preprocessing pipeline created successfully
2021-02-18 14:26:08,056:ERROR:(Process Exit): setup has been interupted with user command 'quit'. setup must rerun.
2021-02-18 14:26:08,057:INFO:Creating global containers
2021-02-18 14:26:08,060:INFO:Internal pipeline: Pipeline(memory=None, steps=[('empty_step', 'passthrough')], verbose=False)
2021-02-18 14:27:14,971:INFO:Creating grid variables
2021-02-18 14:27:15,023:INFO:create_model_container: 0
2021-02-18 14:27:15,024:INFO:master_model_container: 0
2021-02-18 14:27:15,024:INFO:display_container: 0
2021-02-18 14:27:15,033:INFO:Pipeline(memory=None,
         steps=[('dtypes',
                 DataTypes_Auto_infer(categorical_features=[],
                                      display_types=True, features_todrop=[],
                                      id_columns=[], ml_usecase='regression',
                                      numerical_features=[], target='No-show',
                                      time_features=[])),
                ('imputer',
                 Simple_Imputer(categorical_strategy='not_available',
                                fill_value_categorical=None,
                                fill_value_numerical=None,
                                numeric_strategy...
                ('scaling', 'passthrough'), ('P_transform', 'passthrough'),
                ('binn', 'passthrough'), ('rem_outliers', 'passthrough'),
                ('cluster_all', 'passthrough'),
                ('dummy', Dummify(target='No-show')),
                ('fix_perfect', Remove_100(target='No-show')),
                ('clean_names', Clean_Colum_Names()),
                ('feature_select', 'passthrough'), ('fix_multi', 'passthrough'),
                ('dfs', 'passthrough'), ('pca', 'passthrough')],
         verbose=False)
2021-02-18 14:27:15,033:INFO:setup() succesfully completed......................................
2021-02-18 14:27:46,034:INFO:Initializing compare_models()
2021-02-18 14:27:46,034:INFO:compare_models(include=None, fold=None, round=4, cross_validation=True, sort=Accuracy, n_select=1, budget_time=None, turbo=True, errors=ignore, fit_kwargs=None, groups=None, verbose=True, display=None, exclude=None)
2021-02-18 14:27:46,035:INFO:Checking exceptions
2021-02-18 14:27:46,052:INFO:Preparing display monitor
2021-02-18 14:27:46,052:INFO:Preparing display monitor
2021-02-18 14:27:46,096:INFO:Initializing Logistic Regression
2021-02-18 14:27:46,096:INFO:Total runtime is 0.0 minutes
2021-02-18 14:27:46,119:INFO:SubProcess create_model() called ==================================
2021-02-18 14:27:46,119:INFO:Initializing create_model()
2021-02-18 14:27:46,119:INFO:create_model(estimator=lr, fold=StratifiedKFold(n_splits=10, random_state=6396, shuffle=False), round=4, cross_validation=True, predict=True, fit_kwargs={}, groups=None, refit=False, verbose=False, system=False, metrics=None, display=<pycaret.internal.Display.Display object at 0x000001D78F25C4F0>, kwargs={})
2021-02-18 14:27:46,119:INFO:Checking exceptions
2021-02-18 14:27:46,120:INFO:Importing libraries
2021-02-18 14:27:46,120:INFO:Copying training dataset
2021-02-18 14:27:46,152:INFO:Defining folds
2021-02-18 14:27:46,152:INFO:Declaring metric variables
2021-02-18 14:27:46,165:INFO:Importing untrained model
2021-02-18 14:27:46,176:INFO:Logistic Regression Imported succesfully
2021-02-18 14:27:46,205:INFO:Starting cross validation
2021-02-18 14:27:46,206:INFO:Cross validating with StratifiedKFold(n_splits=10, random_state=6396, shuffle=False), n_jobs=-1
2021-02-18 14:28:55,802:WARNING:create_model() for lr raised an exception or returned all 0.0, trying without fit_kwargs:
2021-02-18 14:28:55,813:WARNING:joblib.externals.loky.process_executor._RemoteTraceback: 
"""
Traceback (most recent call last):
  File "C:\Users\PMMCardoso\anaconda3\lib\site-packages\joblib\externals\loky\process_executor.py", line 431, in _process_worker
    r = call_item()
  File "C:\Users\PMMCardoso\anaconda3\lib\site-packages\joblib\externals\loky\process_executor.py", line 285, in __call__
    return self.fn(*self.args, **self.kwargs)
  File "C:\Users\PMMCardoso\anaconda3\lib\site-packages\joblib\_parallel_backends.py", line 595, in __call__
    return self.func(*args, **kwargs)
  File "C:\Users\PMMCardoso\anaconda3\lib\site-packages\joblib\parallel.py", line 262, in __call__
    return [func(*args, **kwargs)
  File "C:\Users\PMMCardoso\anaconda3\lib\site-packages\joblib\parallel.py", line 262, in <listcomp>
    return [func(*args, **kwargs)
  File "C:\Users\PMMCardoso\anaconda3\lib\site-packages\sklearn\model_selection\_validation.py", line 560, in _fit_and_score
    test_scores = _score(estimator, X_test, y_test, scorer)
  File "C:\Users\PMMCardoso\anaconda3\lib\site-packages\sklearn\model_selection\_validation.py", line 607, in _score
    scores = scorer(estimator, X_test, y_test)
  File "C:\Users\PMMCardoso\anaconda3\lib\site-packages\sklearn\metrics\_scorer.py", line 87, in __call__
    score = scorer._score(cached_call, estimator,
  File "C:\Users\PMMCardoso\anaconda3\lib\site-packages\sklearn\metrics\_scorer.py", line 212, in _score
    return self._sign * self._score_func(y_true, y_pred,
  File "C:\Users\PMMCardoso\anaconda3\lib\site-packages\pycaret\internal\metrics.py", line 10, in wrapper
    return score_func(y_true, y_pred, **kwargs)
  File "C:\Users\PMMCardoso\anaconda3\lib\site-packages\sklearn\utils\validation.py", line 72, in inner_f
    return f(**kwargs)
  File "C:\Users\PMMCardoso\anaconda3\lib\site-packages\sklearn\metrics\_classification.py", line 1735, in recall_score
    _, r, _, _ = precision_recall_fscore_support(y_true, y_pred,
  File "C:\Users\PMMCardoso\anaconda3\lib\site-packages\sklearn\utils\validation.py", line 72, in inner_f
    return f(**kwargs)
  File "C:\Users\PMMCardoso\anaconda3\lib\site-packages\sklearn\metrics\_classification.py", line 1433, in precision_recall_fscore_support
    labels = _check_set_wise_labels(y_true, y_pred, average, labels,
  File "C:\Users\PMMCardoso\anaconda3\lib\site-packages\sklearn\metrics\_classification.py", line 1256, in _check_set_wise_labels
    raise ValueError("pos_label=%r is not a valid label: "
ValueError: pos_label=1 is not a valid label: array(['0.0', '1.0'], dtype='<U3')
"""

The above exception was the direct cause of the following exception:

Traceback (most recent call last):
  File "C:\Users\PMMCardoso\anaconda3\lib\site-packages\pycaret\internal\tabular.py", line 2136, in compare_models
    model, model_fit_time = create_model_supervised(
  File "C:\Users\PMMCardoso\anaconda3\lib\site-packages\pycaret\internal\tabular.py", line 3085, in create_model_supervised
    scores = cross_validate(
  File "C:\Users\PMMCardoso\anaconda3\lib\site-packages\sklearn\utils\validation.py", line 72, in inner_f
    return f(**kwargs)
  File "C:\Users\PMMCardoso\anaconda3\lib\site-packages\sklearn\model_selection\_validation.py", line 242, in cross_validate
    scores = parallel(
  File "C:\Users\PMMCardoso\anaconda3\lib\site-packages\joblib\parallel.py", line 1061, in __call__
    self.retrieve()
  File "C:\Users\PMMCardoso\anaconda3\lib\site-packages\joblib\parallel.py", line 940, in retrieve
    self._output.extend(job.get(timeout=self.timeout))
  File "C:\Users\PMMCardoso\anaconda3\lib\site-packages\joblib\_parallel_backends.py", line 542, in wrap_future_result
    return future.result(timeout=timeout)
  File "C:\Users\PMMCardoso\anaconda3\lib\concurrent\futures\_base.py", line 439, in result
    return self.__get_result()
  File "C:\Users\PMMCardoso\anaconda3\lib\concurrent\futures\_base.py", line 388, in __get_result
    raise self._exception
ValueError: pos_label=1 is not a valid label: array(['0.0', '1.0'], dtype='<U3')

2021-02-18 14:28:55,813:INFO:Initializing create_model()
2021-02-18 14:28:55,813:INFO:create_model(estimator=lr, fold=StratifiedKFold(n_splits=10, random_state=6396, shuffle=False), round=4, cross_validation=True, predict=True, fit_kwargs=None, groups=None, refit=False, verbose=False, system=False, metrics=None, display=<pycaret.internal.Display.Display object at 0x000001D78F25C4F0>, kwargs={})
2021-02-18 14:28:55,813:INFO:Checking exceptions
2021-02-18 14:28:55,814:INFO:Importing libraries
2021-02-18 14:28:55,814:INFO:Copying training dataset
2021-02-18 14:28:55,842:INFO:Defining folds
2021-02-18 14:28:55,842:INFO:Declaring metric variables
2021-02-18 14:28:55,856:INFO:Importing untrained model
2021-02-18 14:28:55,866:INFO:Logistic Regression Imported succesfully
2021-02-18 14:28:55,900:INFO:Starting cross validation
2021-02-18 14:28:55,901:INFO:Cross validating with StratifiedKFold(n_splits=10, random_state=6396, shuffle=False), n_jobs=-1
2021-02-18 14:30:06,288:ERROR:create_model() for lr raised an exception:
2021-02-18 14:30:06,291:ERROR:joblib.externals.loky.process_executor._RemoteTraceback: 
"""
Traceback (most recent call last):
  File "C:\Users\PMMCardoso\anaconda3\lib\site-packages\joblib\externals\loky\process_executor.py", line 431, in _process_worker
    r = call_item()
  File "C:\Users\PMMCardoso\anaconda3\lib\site-packages\joblib\externals\loky\process_executor.py", line 285, in __call__
    return self.fn(*self.args, **self.kwargs)
  File "C:\Users\PMMCardoso\anaconda3\lib\site-packages\joblib\_parallel_backends.py", line 595, in __call__
    return self.func(*args, **kwargs)
  File "C:\Users\PMMCardoso\anaconda3\lib\site-packages\joblib\parallel.py", line 262, in __call__
    return [func(*args, **kwargs)
  File "C:\Users\PMMCardoso\anaconda3\lib\site-packages\joblib\parallel.py", line 262, in <listcomp>
    return [func(*args, **kwargs)
  File "C:\Users\PMMCardoso\anaconda3\lib\site-packages\sklearn\model_selection\_validation.py", line 560, in _fit_and_score
    test_scores = _score(estimator, X_test, y_test, scorer)
  File "C:\Users\PMMCardoso\anaconda3\lib\site-packages\sklearn\model_selection\_validation.py", line 607, in _score
    scores = scorer(estimator, X_test, y_test)
  File "C:\Users\PMMCardoso\anaconda3\lib\site-packages\sklearn\metrics\_scorer.py", line 87, in __call__
    score = scorer._score(cached_call, estimator,
  File "C:\Users\PMMCardoso\anaconda3\lib\site-packages\sklearn\metrics\_scorer.py", line 212, in _score
    return self._sign * self._score_func(y_true, y_pred,
  File "C:\Users\PMMCardoso\anaconda3\lib\site-packages\pycaret\internal\metrics.py", line 10, in wrapper
    return score_func(y_true, y_pred, **kwargs)
  File "C:\Users\PMMCardoso\anaconda3\lib\site-packages\sklearn\utils\validation.py", line 72, in inner_f
    return f(**kwargs)
  File "C:\Users\PMMCardoso\anaconda3\lib\site-packages\sklearn\metrics\_classification.py", line 1735, in recall_score
    _, r, _, _ = precision_recall_fscore_support(y_true, y_pred,
  File "C:\Users\PMMCardoso\anaconda3\lib\site-packages\sklearn\utils\validation.py", line 72, in inner_f
    return f(**kwargs)
  File "C:\Users\PMMCardoso\anaconda3\lib\site-packages\sklearn\metrics\_classification.py", line 1433, in precision_recall_fscore_support
    labels = _check_set_wise_labels(y_true, y_pred, average, labels,
  File "C:\Users\PMMCardoso\anaconda3\lib\site-packages\sklearn\metrics\_classification.py", line 1256, in _check_set_wise_labels
    raise ValueError("pos_label=%r is not a valid label: "
ValueError: pos_label=1 is not a valid label: array(['0.0', '1.0'], dtype='<U3')
"""

The above exception was the direct cause of the following exception:

Traceback (most recent call last):
  File "C:\Users\PMMCardoso\anaconda3\lib\site-packages\pycaret\internal\tabular.py", line 2156, in compare_models
    model, model_fit_time = create_model_supervised(
  File "C:\Users\PMMCardoso\anaconda3\lib\site-packages\pycaret\internal\tabular.py", line 3085, in create_model_supervised
    scores = cross_validate(
  File "C:\Users\PMMCardoso\anaconda3\lib\site-packages\sklearn\utils\validation.py", line 72, in inner_f
    return f(**kwargs)
  File "C:\Users\PMMCardoso\anaconda3\lib\site-packages\sklearn\model_selection\_validation.py", line 242, in cross_validate
    scores = parallel(
  File "C:\Users\PMMCardoso\anaconda3\lib\site-packages\joblib\parallel.py", line 1061, in __call__
    self.retrieve()
  File "C:\Users\PMMCardoso\anaconda3\lib\site-packages\joblib\parallel.py", line 940, in retrieve
    self._output.extend(job.get(timeout=self.timeout))
  File "C:\Users\PMMCardoso\anaconda3\lib\site-packages\joblib\_parallel_backends.py", line 542, in wrap_future_result
    return future.result(timeout=timeout)
  File "C:\Users\PMMCardoso\anaconda3\lib\concurrent\futures\_base.py", line 439, in result
    return self.__get_result()
  File "C:\Users\PMMCardoso\anaconda3\lib\concurrent\futures\_base.py", line 388, in __get_result
    raise self._exception
ValueError: pos_label=1 is not a valid label: array(['0.0', '1.0'], dtype='<U3')

2021-02-18 14:30:06,291:INFO:Initializing K Neighbors Classifier
2021-02-18 14:30:06,291:INFO:Total runtime is 2.336583499113719 minutes
2021-02-18 14:30:06,310:INFO:SubProcess create_model() called ==================================
2021-02-18 14:30:06,311:INFO:Initializing create_model()
2021-02-18 14:30:06,311:INFO:create_model(estimator=knn, fold=StratifiedKFold(n_splits=10, random_state=6396, shuffle=False), round=4, cross_validation=True, predict=True, fit_kwargs={}, groups=None, refit=False, verbose=False, system=False, metrics=None, display=<pycaret.internal.Display.Display object at 0x000001D78F25C4F0>, kwargs={})
2021-02-18 14:30:06,312:INFO:Checking exceptions
2021-02-18 14:30:06,312:INFO:Importing libraries
2021-02-18 14:30:06,313:INFO:Copying training dataset
2021-02-18 14:30:06,342:INFO:Defining folds
2021-02-18 14:30:06,342:INFO:Declaring metric variables
2021-02-18 14:30:06,355:INFO:Importing untrained model
2021-02-18 14:30:06,371:INFO:K Neighbors Classifier Imported succesfully
2021-02-18 14:30:06,402:INFO:Starting cross validation
2021-02-18 14:30:06,403:INFO:Cross validating with StratifiedKFold(n_splits=10, random_state=6396, shuffle=False), n_jobs=-1
2021-02-18 14:30:25,386:WARNING:create_model() for knn raised an exception or returned all 0.0, trying without fit_kwargs:
2021-02-18 14:30:25,387:WARNING:joblib.externals.loky.process_executor._RemoteTraceback: 
"""
Traceback (most recent call last):
  File "C:\Users\PMMCardoso\anaconda3\lib\site-packages\joblib\externals\loky\process_executor.py", line 431, in _process_worker
    r = call_item()
  File "C:\Users\PMMCardoso\anaconda3\lib\site-packages\joblib\externals\loky\process_executor.py", line 285, in __call__
    return self.fn(*self.args, **self.kwargs)
  File "C:\Users\PMMCardoso\anaconda3\lib\site-packages\joblib\_parallel_backends.py", line 595, in __call__
    return self.func(*args, **kwargs)
  File "C:\Users\PMMCardoso\anaconda3\lib\site-packages\joblib\parallel.py", line 262, in __call__
    return [func(*args, **kwargs)
  File "C:\Users\PMMCardoso\anaconda3\lib\site-packages\joblib\parallel.py", line 262, in <listcomp>
    return [func(*args, **kwargs)
  File "C:\Users\PMMCardoso\anaconda3\lib\site-packages\sklearn\model_selection\_validation.py", line 560, in _fit_and_score
    test_scores = _score(estimator, X_test, y_test, scorer)
  File "C:\Users\PMMCardoso\anaconda3\lib\site-packages\sklearn\model_selection\_validation.py", line 607, in _score
    scores = scorer(estimator, X_test, y_test)
  File "C:\Users\PMMCardoso\anaconda3\lib\site-packages\sklearn\metrics\_scorer.py", line 87, in __call__
    score = scorer._score(cached_call, estimator,
  File "C:\Users\PMMCardoso\anaconda3\lib\site-packages\sklearn\metrics\_scorer.py", line 212, in _score
    return self._sign * self._score_func(y_true, y_pred,
  File "C:\Users\PMMCardoso\anaconda3\lib\site-packages\pycaret\internal\metrics.py", line 10, in wrapper
    return score_func(y_true, y_pred, **kwargs)
  File "C:\Users\PMMCardoso\anaconda3\lib\site-packages\sklearn\utils\validation.py", line 72, in inner_f
    return f(**kwargs)
  File "C:\Users\PMMCardoso\anaconda3\lib\site-packages\sklearn\metrics\_classification.py", line 1735, in recall_score
    _, r, _, _ = precision_recall_fscore_support(y_true, y_pred,
  File "C:\Users\PMMCardoso\anaconda3\lib\site-packages\sklearn\utils\validation.py", line 72, in inner_f
    return f(**kwargs)
  File "C:\Users\PMMCardoso\anaconda3\lib\site-packages\sklearn\metrics\_classification.py", line 1433, in precision_recall_fscore_support
    labels = _check_set_wise_labels(y_true, y_pred, average, labels,
  File "C:\Users\PMMCardoso\anaconda3\lib\site-packages\sklearn\metrics\_classification.py", line 1256, in _check_set_wise_labels
    raise ValueError("pos_label=%r is not a valid label: "
ValueError: pos_label=1 is not a valid label: array(['0.0', '1.0'], dtype='<U3')
"""

The above exception was the direct cause of the following exception:

Traceback (most recent call last):
  File "C:\Users\PMMCardoso\anaconda3\lib\site-packages\pycaret\internal\tabular.py", line 2136, in compare_models
    model, model_fit_time = create_model_supervised(
  File "C:\Users\PMMCardoso\anaconda3\lib\site-packages\pycaret\internal\tabular.py", line 3085, in create_model_supervised
    scores = cross_validate(
  File "C:\Users\PMMCardoso\anaconda3\lib\site-packages\sklearn\utils\validation.py", line 72, in inner_f
    return f(**kwargs)
  File "C:\Users\PMMCardoso\anaconda3\lib\site-packages\sklearn\model_selection\_validation.py", line 242, in cross_validate
    scores = parallel(
  File "C:\Users\PMMCardoso\anaconda3\lib\site-packages\joblib\parallel.py", line 1061, in __call__
    self.retrieve()
  File "C:\Users\PMMCardoso\anaconda3\lib\site-packages\joblib\parallel.py", line 940, in retrieve
    self._output.extend(job.get(timeout=self.timeout))
  File "C:\Users\PMMCardoso\anaconda3\lib\site-packages\joblib\_parallel_backends.py", line 542, in wrap_future_result
    return future.result(timeout=timeout)
  File "C:\Users\PMMCardoso\anaconda3\lib\concurrent\futures\_base.py", line 439, in result
    return self.__get_result()
  File "C:\Users\PMMCardoso\anaconda3\lib\concurrent\futures\_base.py", line 388, in __get_result
    raise self._exception
ValueError: pos_label=1 is not a valid label: array(['0.0', '1.0'], dtype='<U3')

2021-02-18 14:30:25,387:INFO:Initializing create_model()
2021-02-18 14:30:25,388:INFO:create_model(estimator=knn, fold=StratifiedKFold(n_splits=10, random_state=6396, shuffle=False), round=4, cross_validation=True, predict=True, fit_kwargs=None, groups=None, refit=False, verbose=False, system=False, metrics=None, display=<pycaret.internal.Display.Display object at 0x000001D78F25C4F0>, kwargs={})
2021-02-18 14:30:25,388:INFO:Checking exceptions
2021-02-18 14:30:25,388:INFO:Importing libraries
2021-02-18 14:30:25,389:INFO:Copying training dataset
2021-02-18 14:30:25,432:INFO:Defining folds
2021-02-18 14:30:25,432:INFO:Declaring metric variables
2021-02-18 14:30:25,450:INFO:Importing untrained model
2021-02-18 14:30:25,475:INFO:K Neighbors Classifier Imported succesfully
2021-02-18 14:30:25,515:INFO:Starting cross validation
2021-02-18 14:30:25,516:INFO:Cross validating with StratifiedKFold(n_splits=10, random_state=6396, shuffle=False), n_jobs=-1
2021-02-18 14:30:45,574:ERROR:create_model() for knn raised an exception:
2021-02-18 14:30:45,576:ERROR:joblib.externals.loky.process_executor._RemoteTraceback: 
"""
Traceback (most recent call last):
  File "C:\Users\PMMCardoso\anaconda3\lib\site-packages\joblib\externals\loky\process_executor.py", line 431, in _process_worker
    r = call_item()
  File "C:\Users\PMMCardoso\anaconda3\lib\site-packages\joblib\externals\loky\process_executor.py", line 285, in __call__
    return self.fn(*self.args, **self.kwargs)
  File "C:\Users\PMMCardoso\anaconda3\lib\site-packages\joblib\_parallel_backends.py", line 595, in __call__
    return self.func(*args, **kwargs)
  File "C:\Users\PMMCardoso\anaconda3\lib\site-packages\joblib\parallel.py", line 262, in __call__
    return [func(*args, **kwargs)
  File "C:\Users\PMMCardoso\anaconda3\lib\site-packages\joblib\parallel.py", line 262, in <listcomp>
    return [func(*args, **kwargs)
  File "C:\Users\PMMCardoso\anaconda3\lib\site-packages\sklearn\model_selection\_validation.py", line 560, in _fit_and_score
    test_scores = _score(estimator, X_test, y_test, scorer)
  File "C:\Users\PMMCardoso\anaconda3\lib\site-packages\sklearn\model_selection\_validation.py", line 607, in _score
    scores = scorer(estimator, X_test, y_test)
  File "C:\Users\PMMCardoso\anaconda3\lib\site-packages\sklearn\metrics\_scorer.py", line 87, in __call__
    score = scorer._score(cached_call, estimator,
  File "C:\Users\PMMCardoso\anaconda3\lib\site-packages\sklearn\metrics\_scorer.py", line 212, in _score
    return self._sign * self._score_func(y_true, y_pred,
  File "C:\Users\PMMCardoso\anaconda3\lib\site-packages\pycaret\internal\metrics.py", line 10, in wrapper
    return score_func(y_true, y_pred, **kwargs)
  File "C:\Users\PMMCardoso\anaconda3\lib\site-packages\sklearn\utils\validation.py", line 72, in inner_f
    return f(**kwargs)
  File "C:\Users\PMMCardoso\anaconda3\lib\site-packages\sklearn\metrics\_classification.py", line 1735, in recall_score
    _, r, _, _ = precision_recall_fscore_support(y_true, y_pred,
  File "C:\Users\PMMCardoso\anaconda3\lib\site-packages\sklearn\utils\validation.py", line 72, in inner_f
    return f(**kwargs)
  File "C:\Users\PMMCardoso\anaconda3\lib\site-packages\sklearn\metrics\_classification.py", line 1433, in precision_recall_fscore_support
    labels = _check_set_wise_labels(y_true, y_pred, average, labels,
  File "C:\Users\PMMCardoso\anaconda3\lib\site-packages\sklearn\metrics\_classification.py", line 1256, in _check_set_wise_labels
    raise ValueError("pos_label=%r is not a valid label: "
ValueError: pos_label=1 is not a valid label: array(['0.0', '1.0'], dtype='<U3')
"""

The above exception was the direct cause of the following exception:

Traceback (most recent call last):
  File "C:\Users\PMMCardoso\anaconda3\lib\site-packages\pycaret\internal\tabular.py", line 2156, in compare_models
    model, model_fit_time = create_model_supervised(
  File "C:\Users\PMMCardoso\anaconda3\lib\site-packages\pycaret\internal\tabular.py", line 3085, in create_model_supervised
    scores = cross_validate(
  File "C:\Users\PMMCardoso\anaconda3\lib\site-packages\sklearn\utils\validation.py", line 72, in inner_f
    return f(**kwargs)
  File "C:\Users\PMMCardoso\anaconda3\lib\site-packages\sklearn\model_selection\_validation.py", line 242, in cross_validate
    scores = parallel(
  File "C:\Users\PMMCardoso\anaconda3\lib\site-packages\joblib\parallel.py", line 1061, in __call__
    self.retrieve()
  File "C:\Users\PMMCardoso\anaconda3\lib\site-packages\joblib\parallel.py", line 940, in retrieve
    self._output.extend(job.get(timeout=self.timeout))
  File "C:\Users\PMMCardoso\anaconda3\lib\site-packages\joblib\_parallel_backends.py", line 542, in wrap_future_result
    return future.result(timeout=timeout)
  File "C:\Users\PMMCardoso\anaconda3\lib\concurrent\futures\_base.py", line 439, in result
    return self.__get_result()
  File "C:\Users\PMMCardoso\anaconda3\lib\concurrent\futures\_base.py", line 388, in __get_result
    raise self._exception
ValueError: pos_label=1 is not a valid label: array(['0.0', '1.0'], dtype='<U3')

2021-02-18 14:30:45,577:INFO:Initializing Naive Bayes
2021-02-18 14:30:45,577:INFO:Total runtime is 2.9913654685020448 minutes
2021-02-18 14:30:45,599:INFO:SubProcess create_model() called ==================================
2021-02-18 14:30:45,600:INFO:Initializing create_model()
2021-02-18 14:30:45,600:INFO:create_model(estimator=nb, fold=StratifiedKFold(n_splits=10, random_state=6396, shuffle=False), round=4, cross_validation=True, predict=True, fit_kwargs={}, groups=None, refit=False, verbose=False, system=False, metrics=None, display=<pycaret.internal.Display.Display object at 0x000001D78F25C4F0>, kwargs={})
2021-02-18 14:30:45,600:INFO:Checking exceptions
2021-02-18 14:30:45,600:INFO:Importing libraries
2021-02-18 14:30:45,600:INFO:Copying training dataset
2021-02-18 14:30:45,631:INFO:Defining folds
2021-02-18 14:30:45,632:INFO:Declaring metric variables
2021-02-18 14:30:45,646:INFO:Importing untrained model
2021-02-18 14:30:45,661:INFO:Naive Bayes Imported succesfully
2021-02-18 14:30:45,696:INFO:Starting cross validation
2021-02-18 14:30:45,697:INFO:Cross validating with StratifiedKFold(n_splits=10, random_state=6396, shuffle=False), n_jobs=-1
2021-02-18 14:30:55,130:WARNING:create_model() for nb raised an exception or returned all 0.0, trying without fit_kwargs:
2021-02-18 14:30:55,132:WARNING:joblib.externals.loky.process_executor._RemoteTraceback: 
"""
Traceback (most recent call last):
  File "C:\Users\PMMCardoso\anaconda3\lib\site-packages\joblib\externals\loky\process_executor.py", line 431, in _process_worker
    r = call_item()
  File "C:\Users\PMMCardoso\anaconda3\lib\site-packages\joblib\externals\loky\process_executor.py", line 285, in __call__
    return self.fn(*self.args, **self.kwargs)
  File "C:\Users\PMMCardoso\anaconda3\lib\site-packages\joblib\_parallel_backends.py", line 595, in __call__
    return self.func(*args, **kwargs)
  File "C:\Users\PMMCardoso\anaconda3\lib\site-packages\joblib\parallel.py", line 262, in __call__
    return [func(*args, **kwargs)
  File "C:\Users\PMMCardoso\anaconda3\lib\site-packages\joblib\parallel.py", line 262, in <listcomp>
    return [func(*args, **kwargs)
  File "C:\Users\PMMCardoso\anaconda3\lib\site-packages\sklearn\model_selection\_validation.py", line 560, in _fit_and_score
    test_scores = _score(estimator, X_test, y_test, scorer)
  File "C:\Users\PMMCardoso\anaconda3\lib\site-packages\sklearn\model_selection\_validation.py", line 607, in _score
    scores = scorer(estimator, X_test, y_test)
  File "C:\Users\PMMCardoso\anaconda3\lib\site-packages\sklearn\metrics\_scorer.py", line 87, in __call__
    score = scorer._score(cached_call, estimator,
  File "C:\Users\PMMCardoso\anaconda3\lib\site-packages\sklearn\metrics\_scorer.py", line 212, in _score
    return self._sign * self._score_func(y_true, y_pred,
  File "C:\Users\PMMCardoso\anaconda3\lib\site-packages\pycaret\internal\metrics.py", line 10, in wrapper
    return score_func(y_true, y_pred, **kwargs)
  File "C:\Users\PMMCardoso\anaconda3\lib\site-packages\sklearn\utils\validation.py", line 72, in inner_f
    return f(**kwargs)
  File "C:\Users\PMMCardoso\anaconda3\lib\site-packages\sklearn\metrics\_classification.py", line 1735, in recall_score
    _, r, _, _ = precision_recall_fscore_support(y_true, y_pred,
  File "C:\Users\PMMCardoso\anaconda3\lib\site-packages\sklearn\utils\validation.py", line 72, in inner_f
    return f(**kwargs)
  File "C:\Users\PMMCardoso\anaconda3\lib\site-packages\sklearn\metrics\_classification.py", line 1433, in precision_recall_fscore_support
    labels = _check_set_wise_labels(y_true, y_pred, average, labels,
  File "C:\Users\PMMCardoso\anaconda3\lib\site-packages\sklearn\metrics\_classification.py", line 1256, in _check_set_wise_labels
    raise ValueError("pos_label=%r is not a valid label: "
ValueError: pos_label=1 is not a valid label: array(['0.0', '1.0'], dtype='<U3')
"""

The above exception was the direct cause of the following exception:

Traceback (most recent call last):
  File "C:\Users\PMMCardoso\anaconda3\lib\site-packages\pycaret\internal\tabular.py", line 2136, in compare_models
    model, model_fit_time = create_model_supervised(
  File "C:\Users\PMMCardoso\anaconda3\lib\site-packages\pycaret\internal\tabular.py", line 3085, in create_model_supervised
    scores = cross_validate(
  File "C:\Users\PMMCardoso\anaconda3\lib\site-packages\sklearn\utils\validation.py", line 72, in inner_f
    return f(**kwargs)
  File "C:\Users\PMMCardoso\anaconda3\lib\site-packages\sklearn\model_selection\_validation.py", line 242, in cross_validate
    scores = parallel(
  File "C:\Users\PMMCardoso\anaconda3\lib\site-packages\joblib\parallel.py", line 1061, in __call__
    self.retrieve()
  File "C:\Users\PMMCardoso\anaconda3\lib\site-packages\joblib\parallel.py", line 940, in retrieve
    self._output.extend(job.get(timeout=self.timeout))
  File "C:\Users\PMMCardoso\anaconda3\lib\site-packages\joblib\_parallel_backends.py", line 542, in wrap_future_result
    return future.result(timeout=timeout)
  File "C:\Users\PMMCardoso\anaconda3\lib\concurrent\futures\_base.py", line 439, in result
    return self.__get_result()
  File "C:\Users\PMMCardoso\anaconda3\lib\concurrent\futures\_base.py", line 388, in __get_result
    raise self._exception
ValueError: pos_label=1 is not a valid label: array(['0.0', '1.0'], dtype='<U3')

2021-02-18 14:30:55,133:INFO:Initializing create_model()
2021-02-18 14:30:55,133:INFO:create_model(estimator=nb, fold=StratifiedKFold(n_splits=10, random_state=6396, shuffle=False), round=4, cross_validation=True, predict=True, fit_kwargs=None, groups=None, refit=False, verbose=False, system=False, metrics=None, display=<pycaret.internal.Display.Display object at 0x000001D78F25C4F0>, kwargs={})
2021-02-18 14:30:55,133:INFO:Checking exceptions
2021-02-18 14:30:55,133:INFO:Importing libraries
2021-02-18 14:30:55,133:INFO:Copying training dataset
2021-02-18 14:30:55,177:INFO:Defining folds
2021-02-18 14:30:55,178:INFO:Declaring metric variables
2021-02-18 14:30:55,196:INFO:Importing untrained model
2021-02-18 14:30:55,215:INFO:Naive Bayes Imported succesfully
2021-02-18 14:30:55,281:INFO:Starting cross validation
2021-02-18 14:30:55,282:INFO:Cross validating with StratifiedKFold(n_splits=10, random_state=6396, shuffle=False), n_jobs=-1
2021-02-18 14:31:03,762:ERROR:create_model() for nb raised an exception:
2021-02-18 14:31:03,763:ERROR:joblib.externals.loky.process_executor._RemoteTraceback: 
"""
Traceback (most recent call last):
  File "C:\Users\PMMCardoso\anaconda3\lib\site-packages\joblib\externals\loky\process_executor.py", line 431, in _process_worker
    r = call_item()
  File "C:\Users\PMMCardoso\anaconda3\lib\site-packages\joblib\externals\loky\process_executor.py", line 285, in __call__
    return self.fn(*self.args, **self.kwargs)
  File "C:\Users\PMMCardoso\anaconda3\lib\site-packages\joblib\_parallel_backends.py", line 595, in __call__
    return self.func(*args, **kwargs)
  File "C:\Users\PMMCardoso\anaconda3\lib\site-packages\joblib\parallel.py", line 262, in __call__
    return [func(*args, **kwargs)
  File "C:\Users\PMMCardoso\anaconda3\lib\site-packages\joblib\parallel.py", line 262, in <listcomp>
    return [func(*args, **kwargs)
  File "C:\Users\PMMCardoso\anaconda3\lib\site-packages\sklearn\model_selection\_validation.py", line 560, in _fit_and_score
    test_scores = _score(estimator, X_test, y_test, scorer)
  File "C:\Users\PMMCardoso\anaconda3\lib\site-packages\sklearn\model_selection\_validation.py", line 607, in _score
    scores = scorer(estimator, X_test, y_test)
  File "C:\Users\PMMCardoso\anaconda3\lib\site-packages\sklearn\metrics\_scorer.py", line 87, in __call__
    score = scorer._score(cached_call, estimator,
  File "C:\Users\PMMCardoso\anaconda3\lib\site-packages\sklearn\metrics\_scorer.py", line 212, in _score
    return self._sign * self._score_func(y_true, y_pred,
  File "C:\Users\PMMCardoso\anaconda3\lib\site-packages\pycaret\internal\metrics.py", line 10, in wrapper
    return score_func(y_true, y_pred, **kwargs)
  File "C:\Users\PMMCardoso\anaconda3\lib\site-packages\sklearn\utils\validation.py", line 72, in inner_f
    return f(**kwargs)
  File "C:\Users\PMMCardoso\anaconda3\lib\site-packages\sklearn\metrics\_classification.py", line 1735, in recall_score
    _, r, _, _ = precision_recall_fscore_support(y_true, y_pred,
  File "C:\Users\PMMCardoso\anaconda3\lib\site-packages\sklearn\utils\validation.py", line 72, in inner_f
    return f(**kwargs)
  File "C:\Users\PMMCardoso\anaconda3\lib\site-packages\sklearn\metrics\_classification.py", line 1433, in precision_recall_fscore_support
    labels = _check_set_wise_labels(y_true, y_pred, average, labels,
  File "C:\Users\PMMCardoso\anaconda3\lib\site-packages\sklearn\metrics\_classification.py", line 1256, in _check_set_wise_labels
    raise ValueError("pos_label=%r is not a valid label: "
ValueError: pos_label=1 is not a valid label: array(['0.0', '1.0'], dtype='<U3')
"""

The above exception was the direct cause of the following exception:

Traceback (most recent call last):
  File "C:\Users\PMMCardoso\anaconda3\lib\site-packages\pycaret\internal\tabular.py", line 2156, in compare_models
    model, model_fit_time = create_model_supervised(
  File "C:\Users\PMMCardoso\anaconda3\lib\site-packages\pycaret\internal\tabular.py", line 3085, in create_model_supervised
    scores = cross_validate(
  File "C:\Users\PMMCardoso\anaconda3\lib\site-packages\sklearn\utils\validation.py", line 72, in inner_f
    return f(**kwargs)
  File "C:\Users\PMMCardoso\anaconda3\lib\site-packages\sklearn\model_selection\_validation.py", line 242, in cross_validate
    scores = parallel(
  File "C:\Users\PMMCardoso\anaconda3\lib\site-packages\joblib\parallel.py", line 1061, in __call__
    self.retrieve()
  File "C:\Users\PMMCardoso\anaconda3\lib\site-packages\joblib\parallel.py", line 940, in retrieve
    self._output.extend(job.get(timeout=self.timeout))
  File "C:\Users\PMMCardoso\anaconda3\lib\site-packages\joblib\_parallel_backends.py", line 542, in wrap_future_result
    return future.result(timeout=timeout)
  File "C:\Users\PMMCardoso\anaconda3\lib\concurrent\futures\_base.py", line 439, in result
    return self.__get_result()
  File "C:\Users\PMMCardoso\anaconda3\lib\concurrent\futures\_base.py", line 388, in __get_result
    raise self._exception
ValueError: pos_label=1 is not a valid label: array(['0.0', '1.0'], dtype='<U3')

2021-02-18 14:31:03,763:INFO:Initializing Decision Tree Classifier
2021-02-18 14:31:03,763:INFO:Total runtime is 3.2944547533988953 minutes
2021-02-18 14:31:03,776:INFO:SubProcess create_model() called ==================================
2021-02-18 14:31:03,777:INFO:Initializing create_model()
2021-02-18 14:31:03,778:INFO:create_model(estimator=dt, fold=StratifiedKFold(n_splits=10, random_state=6396, shuffle=False), round=4, cross_validation=True, predict=True, fit_kwargs={}, groups=None, refit=False, verbose=False, system=False, metrics=None, display=<pycaret.internal.Display.Display object at 0x000001D78F25C4F0>, kwargs={})
2021-02-18 14:31:03,778:INFO:Checking exceptions
2021-02-18 14:31:03,778:INFO:Importing libraries
2021-02-18 14:31:03,778:INFO:Copying training dataset
2021-02-18 14:31:03,814:INFO:Defining folds
2021-02-18 14:31:03,814:INFO:Declaring metric variables
2021-02-18 14:31:03,829:INFO:Importing untrained model
2021-02-18 14:31:03,844:INFO:Decision Tree Classifier Imported succesfully
2021-02-18 14:31:03,874:INFO:Starting cross validation
2021-02-18 14:31:03,875:INFO:Cross validating with StratifiedKFold(n_splits=10, random_state=6396, shuffle=False), n_jobs=-1
2021-02-18 14:31:16,490:WARNING:create_model() for dt raised an exception or returned all 0.0, trying without fit_kwargs:
2021-02-18 14:31:16,491:WARNING:joblib.externals.loky.process_executor._RemoteTraceback: 
"""
Traceback (most recent call last):
  File "C:\Users\PMMCardoso\anaconda3\lib\site-packages\joblib\externals\loky\process_executor.py", line 431, in _process_worker
    r = call_item()
  File "C:\Users\PMMCardoso\anaconda3\lib\site-packages\joblib\externals\loky\process_executor.py", line 285, in __call__
    return self.fn(*self.args, **self.kwargs)
  File "C:\Users\PMMCardoso\anaconda3\lib\site-packages\joblib\_parallel_backends.py", line 595, in __call__
    return self.func(*args, **kwargs)
  File "C:\Users\PMMCardoso\anaconda3\lib\site-packages\joblib\parallel.py", line 262, in __call__
    return [func(*args, **kwargs)
  File "C:\Users\PMMCardoso\anaconda3\lib\site-packages\joblib\parallel.py", line 262, in <listcomp>
    return [func(*args, **kwargs)
  File "C:\Users\PMMCardoso\anaconda3\lib\site-packages\sklearn\model_selection\_validation.py", line 560, in _fit_and_score
    test_scores = _score(estimator, X_test, y_test, scorer)
  File "C:\Users\PMMCardoso\anaconda3\lib\site-packages\sklearn\model_selection\_validation.py", line 607, in _score
    scores = scorer(estimator, X_test, y_test)
  File "C:\Users\PMMCardoso\anaconda3\lib\site-packages\sklearn\metrics\_scorer.py", line 87, in __call__
    score = scorer._score(cached_call, estimator,
  File "C:\Users\PMMCardoso\anaconda3\lib\site-packages\sklearn\metrics\_scorer.py", line 212, in _score
    return self._sign * self._score_func(y_true, y_pred,
  File "C:\Users\PMMCardoso\anaconda3\lib\site-packages\pycaret\internal\metrics.py", line 10, in wrapper
    return score_func(y_true, y_pred, **kwargs)
  File "C:\Users\PMMCardoso\anaconda3\lib\site-packages\sklearn\utils\validation.py", line 72, in inner_f
    return f(**kwargs)
  File "C:\Users\PMMCardoso\anaconda3\lib\site-packages\sklearn\metrics\_classification.py", line 1735, in recall_score
    _, r, _, _ = precision_recall_fscore_support(y_true, y_pred,
  File "C:\Users\PMMCardoso\anaconda3\lib\site-packages\sklearn\utils\validation.py", line 72, in inner_f
    return f(**kwargs)
  File "C:\Users\PMMCardoso\anaconda3\lib\site-packages\sklearn\metrics\_classification.py", line 1433, in precision_recall_fscore_support
    labels = _check_set_wise_labels(y_true, y_pred, average, labels,
  File "C:\Users\PMMCardoso\anaconda3\lib\site-packages\sklearn\metrics\_classification.py", line 1256, in _check_set_wise_labels
    raise ValueError("pos_label=%r is not a valid label: "
ValueError: pos_label=1 is not a valid label: array(['0.0', '1.0'], dtype='<U3')
"""

The above exception was the direct cause of the following exception:

Traceback (most recent call last):
  File "C:\Users\PMMCardoso\anaconda3\lib\site-packages\pycaret\internal\tabular.py", line 2136, in compare_models
    model, model_fit_time = create_model_supervised(
  File "C:\Users\PMMCardoso\anaconda3\lib\site-packages\pycaret\internal\tabular.py", line 3085, in create_model_supervised
    scores = cross_validate(
  File "C:\Users\PMMCardoso\anaconda3\lib\site-packages\sklearn\utils\validation.py", line 72, in inner_f
    return f(**kwargs)
  File "C:\Users\PMMCardoso\anaconda3\lib\site-packages\sklearn\model_selection\_validation.py", line 242, in cross_validate
    scores = parallel(
  File "C:\Users\PMMCardoso\anaconda3\lib\site-packages\joblib\parallel.py", line 1061, in __call__
    self.retrieve()
  File "C:\Users\PMMCardoso\anaconda3\lib\site-packages\joblib\parallel.py", line 940, in retrieve
    self._output.extend(job.get(timeout=self.timeout))
  File "C:\Users\PMMCardoso\anaconda3\lib\site-packages\joblib\_parallel_backends.py", line 542, in wrap_future_result
    return future.result(timeout=timeout)
  File "C:\Users\PMMCardoso\anaconda3\lib\concurrent\futures\_base.py", line 439, in result
    return self.__get_result()
  File "C:\Users\PMMCardoso\anaconda3\lib\concurrent\futures\_base.py", line 388, in __get_result
    raise self._exception
ValueError: pos_label=1 is not a valid label: array(['0.0', '1.0'], dtype='<U3')

2021-02-18 14:31:16,492:INFO:Initializing create_model()
2021-02-18 14:31:16,492:INFO:create_model(estimator=dt, fold=StratifiedKFold(n_splits=10, random_state=6396, shuffle=False), round=4, cross_validation=True, predict=True, fit_kwargs=None, groups=None, refit=False, verbose=False, system=False, metrics=None, display=<pycaret.internal.Display.Display object at 0x000001D78F25C4F0>, kwargs={})
2021-02-18 14:31:16,492:INFO:Checking exceptions
2021-02-18 14:31:16,492:INFO:Importing libraries
2021-02-18 14:31:16,492:INFO:Copying training dataset
2021-02-18 14:31:16,525:INFO:Defining folds
2021-02-18 14:31:16,525:INFO:Declaring metric variables
2021-02-18 14:31:16,540:INFO:Importing untrained model
2021-02-18 14:31:16,553:INFO:Decision Tree Classifier Imported succesfully
2021-02-18 14:31:16,591:INFO:Starting cross validation
2021-02-18 14:31:16,592:INFO:Cross validating with StratifiedKFold(n_splits=10, random_state=6396, shuffle=False), n_jobs=-1
2021-02-18 14:31:29,341:ERROR:create_model() for dt raised an exception:
2021-02-18 14:31:29,342:ERROR:joblib.externals.loky.process_executor._RemoteTraceback: 
"""
Traceback (most recent call last):
  File "C:\Users\PMMCardoso\anaconda3\lib\site-packages\joblib\externals\loky\process_executor.py", line 431, in _process_worker
    r = call_item()
  File "C:\Users\PMMCardoso\anaconda3\lib\site-packages\joblib\externals\loky\process_executor.py", line 285, in __call__
    return self.fn(*self.args, **self.kwargs)
  File "C:\Users\PMMCardoso\anaconda3\lib\site-packages\joblib\_parallel_backends.py", line 595, in __call__
    return self.func(*args, **kwargs)
  File "C:\Users\PMMCardoso\anaconda3\lib\site-packages\joblib\parallel.py", line 262, in __call__
    return [func(*args, **kwargs)
  File "C:\Users\PMMCardoso\anaconda3\lib\site-packages\joblib\parallel.py", line 262, in <listcomp>
    return [func(*args, **kwargs)
  File "C:\Users\PMMCardoso\anaconda3\lib\site-packages\sklearn\model_selection\_validation.py", line 560, in _fit_and_score
    test_scores = _score(estimator, X_test, y_test, scorer)
  File "C:\Users\PMMCardoso\anaconda3\lib\site-packages\sklearn\model_selection\_validation.py", line 607, in _score
    scores = scorer(estimator, X_test, y_test)
  File "C:\Users\PMMCardoso\anaconda3\lib\site-packages\sklearn\metrics\_scorer.py", line 87, in __call__
    score = scorer._score(cached_call, estimator,
  File "C:\Users\PMMCardoso\anaconda3\lib\site-packages\sklearn\metrics\_scorer.py", line 212, in _score
    return self._sign * self._score_func(y_true, y_pred,
  File "C:\Users\PMMCardoso\anaconda3\lib\site-packages\pycaret\internal\metrics.py", line 10, in wrapper
    return score_func(y_true, y_pred, **kwargs)
  File "C:\Users\PMMCardoso\anaconda3\lib\site-packages\sklearn\utils\validation.py", line 72, in inner_f
    return f(**kwargs)
  File "C:\Users\PMMCardoso\anaconda3\lib\site-packages\sklearn\metrics\_classification.py", line 1735, in recall_score
    _, r, _, _ = precision_recall_fscore_support(y_true, y_pred,
  File "C:\Users\PMMCardoso\anaconda3\lib\site-packages\sklearn\utils\validation.py", line 72, in inner_f
    return f(**kwargs)
  File "C:\Users\PMMCardoso\anaconda3\lib\site-packages\sklearn\metrics\_classification.py", line 1433, in precision_recall_fscore_support
    labels = _check_set_wise_labels(y_true, y_pred, average, labels,
  File "C:\Users\PMMCardoso\anaconda3\lib\site-packages\sklearn\metrics\_classification.py", line 1256, in _check_set_wise_labels
    raise ValueError("pos_label=%r is not a valid label: "
ValueError: pos_label=1 is not a valid label: array(['0.0', '1.0'], dtype='<U3')
"""

The above exception was the direct cause of the following exception:

Traceback (most recent call last):
  File "C:\Users\PMMCardoso\anaconda3\lib\site-packages\pycaret\internal\tabular.py", line 2156, in compare_models
    model, model_fit_time = create_model_supervised(
  File "C:\Users\PMMCardoso\anaconda3\lib\site-packages\pycaret\internal\tabular.py", line 3085, in create_model_supervised
    scores = cross_validate(
  File "C:\Users\PMMCardoso\anaconda3\lib\site-packages\sklearn\utils\validation.py", line 72, in inner_f
    return f(**kwargs)
  File "C:\Users\PMMCardoso\anaconda3\lib\site-packages\sklearn\model_selection\_validation.py", line 242, in cross_validate
    scores = parallel(
  File "C:\Users\PMMCardoso\anaconda3\lib\site-packages\joblib\parallel.py", line 1061, in __call__
    self.retrieve()
  File "C:\Users\PMMCardoso\anaconda3\lib\site-packages\joblib\parallel.py", line 940, in retrieve
    self._output.extend(job.get(timeout=self.timeout))
  File "C:\Users\PMMCardoso\anaconda3\lib\site-packages\joblib\_parallel_backends.py", line 542, in wrap_future_result
    return future.result(timeout=timeout)
  File "C:\Users\PMMCardoso\anaconda3\lib\concurrent\futures\_base.py", line 439, in result
    return self.__get_result()
  File "C:\Users\PMMCardoso\anaconda3\lib\concurrent\futures\_base.py", line 388, in __get_result
    raise self._exception
ValueError: pos_label=1 is not a valid label: array(['0.0', '1.0'], dtype='<U3')

2021-02-18 14:31:29,342:INFO:Initializing SVM - Linear Kernel
2021-02-18 14:31:29,342:INFO:Total runtime is 3.7207811077435813 minutes
2021-02-18 14:31:29,360:INFO:SubProcess create_model() called ==================================
2021-02-18 14:31:29,361:INFO:Initializing create_model()
2021-02-18 14:31:29,361:INFO:create_model(estimator=svm, fold=StratifiedKFold(n_splits=10, random_state=6396, shuffle=False), round=4, cross_validation=True, predict=True, fit_kwargs={}, groups=None, refit=False, verbose=False, system=False, metrics=None, display=<pycaret.internal.Display.Display object at 0x000001D78F25C4F0>, kwargs={})
2021-02-18 14:31:29,361:INFO:Checking exceptions
2021-02-18 14:31:29,361:INFO:Importing libraries
2021-02-18 14:31:29,361:INFO:Copying training dataset
2021-02-18 14:31:29,393:INFO:Defining folds
2021-02-18 14:31:29,393:INFO:Declaring metric variables
2021-02-18 14:31:29,408:INFO:Importing untrained model
2021-02-18 14:31:29,423:INFO:SVM - Linear Kernel Imported succesfully
2021-02-18 14:31:29,456:INFO:Starting cross validation
2021-02-18 14:31:29,457:INFO:Cross validating with StratifiedKFold(n_splits=10, random_state=6396, shuffle=False), n_jobs=-1
2021-02-18 14:32:00,786:WARNING:create_model() for svm raised an exception or returned all 0.0, trying without fit_kwargs:
2021-02-18 14:32:00,787:WARNING:joblib.externals.loky.process_executor._RemoteTraceback: 
"""
Traceback (most recent call last):
  File "C:\Users\PMMCardoso\anaconda3\lib\site-packages\joblib\externals\loky\process_executor.py", line 431, in _process_worker
    r = call_item()
  File "C:\Users\PMMCardoso\anaconda3\lib\site-packages\joblib\externals\loky\process_executor.py", line 285, in __call__
    return self.fn(*self.args, **self.kwargs)
  File "C:\Users\PMMCardoso\anaconda3\lib\site-packages\joblib\_parallel_backends.py", line 595, in __call__
    return self.func(*args, **kwargs)
  File "C:\Users\PMMCardoso\anaconda3\lib\site-packages\joblib\parallel.py", line 262, in __call__
    return [func(*args, **kwargs)
  File "C:\Users\PMMCardoso\anaconda3\lib\site-packages\joblib\parallel.py", line 262, in <listcomp>
    return [func(*args, **kwargs)
  File "C:\Users\PMMCardoso\anaconda3\lib\site-packages\sklearn\model_selection\_validation.py", line 560, in _fit_and_score
    test_scores = _score(estimator, X_test, y_test, scorer)
  File "C:\Users\PMMCardoso\anaconda3\lib\site-packages\sklearn\model_selection\_validation.py", line 607, in _score
    scores = scorer(estimator, X_test, y_test)
  File "C:\Users\PMMCardoso\anaconda3\lib\site-packages\sklearn\metrics\_scorer.py", line 87, in __call__
    score = scorer._score(cached_call, estimator,
  File "C:\Users\PMMCardoso\anaconda3\lib\site-packages\sklearn\metrics\_scorer.py", line 212, in _score
    return self._sign * self._score_func(y_true, y_pred,
  File "C:\Users\PMMCardoso\anaconda3\lib\site-packages\pycaret\internal\metrics.py", line 10, in wrapper
    return score_func(y_true, y_pred, **kwargs)
  File "C:\Users\PMMCardoso\anaconda3\lib\site-packages\sklearn\utils\validation.py", line 72, in inner_f
    return f(**kwargs)
  File "C:\Users\PMMCardoso\anaconda3\lib\site-packages\sklearn\metrics\_classification.py", line 1735, in recall_score
    _, r, _, _ = precision_recall_fscore_support(y_true, y_pred,
  File "C:\Users\PMMCardoso\anaconda3\lib\site-packages\sklearn\utils\validation.py", line 72, in inner_f
    return f(**kwargs)
  File "C:\Users\PMMCardoso\anaconda3\lib\site-packages\sklearn\metrics\_classification.py", line 1433, in precision_recall_fscore_support
    labels = _check_set_wise_labels(y_true, y_pred, average, labels,
  File "C:\Users\PMMCardoso\anaconda3\lib\site-packages\sklearn\metrics\_classification.py", line 1256, in _check_set_wise_labels
    raise ValueError("pos_label=%r is not a valid label: "
ValueError: pos_label=1 is not a valid label: array(['0.0', '1.0'], dtype='<U3')
"""

The above exception was the direct cause of the following exception:

Traceback (most recent call last):
  File "C:\Users\PMMCardoso\anaconda3\lib\site-packages\pycaret\internal\tabular.py", line 2136, in compare_models
    model, model_fit_time = create_model_supervised(
  File "C:\Users\PMMCardoso\anaconda3\lib\site-packages\pycaret\internal\tabular.py", line 3085, in create_model_supervised
    scores = cross_validate(
  File "C:\Users\PMMCardoso\anaconda3\lib\site-packages\sklearn\utils\validation.py", line 72, in inner_f
    return f(**kwargs)
  File "C:\Users\PMMCardoso\anaconda3\lib\site-packages\sklearn\model_selection\_validation.py", line 242, in cross_validate
    scores = parallel(
  File "C:\Users\PMMCardoso\anaconda3\lib\site-packages\joblib\parallel.py", line 1061, in __call__
    self.retrieve()
  File "C:\Users\PMMCardoso\anaconda3\lib\site-packages\joblib\parallel.py", line 940, in retrieve
    self._output.extend(job.get(timeout=self.timeout))
  File "C:\Users\PMMCardoso\anaconda3\lib\site-packages\joblib\_parallel_backends.py", line 542, in wrap_future_result
    return future.result(timeout=timeout)
  File "C:\Users\PMMCardoso\anaconda3\lib\concurrent\futures\_base.py", line 439, in result
    return self.__get_result()
  File "C:\Users\PMMCardoso\anaconda3\lib\concurrent\futures\_base.py", line 388, in __get_result
    raise self._exception
ValueError: pos_label=1 is not a valid label: array(['0.0', '1.0'], dtype='<U3')

2021-02-18 14:32:00,787:INFO:Initializing create_model()
2021-02-18 14:32:00,787:INFO:create_model(estimator=svm, fold=StratifiedKFold(n_splits=10, random_state=6396, shuffle=False), round=4, cross_validation=True, predict=True, fit_kwargs=None, groups=None, refit=False, verbose=False, system=False, metrics=None, display=<pycaret.internal.Display.Display object at 0x000001D78F25C4F0>, kwargs={})
2021-02-18 14:32:00,787:INFO:Checking exceptions
2021-02-18 14:32:00,787:INFO:Importing libraries
2021-02-18 14:32:00,787:INFO:Copying training dataset
2021-02-18 14:32:00,817:INFO:Defining folds
2021-02-18 14:32:00,817:INFO:Declaring metric variables
2021-02-18 14:32:00,830:INFO:Importing untrained model
2021-02-18 14:32:00,847:INFO:SVM - Linear Kernel Imported succesfully
2021-02-18 14:32:00,883:INFO:Starting cross validation
2021-02-18 14:32:00,884:INFO:Cross validating with StratifiedKFold(n_splits=10, random_state=6396, shuffle=False), n_jobs=-1
2021-02-18 14:32:34,130:ERROR:create_model() for svm raised an exception:
2021-02-18 14:32:34,131:ERROR:joblib.externals.loky.process_executor._RemoteTraceback: 
"""
Traceback (most recent call last):
  File "C:\Users\PMMCardoso\anaconda3\lib\site-packages\joblib\externals\loky\process_executor.py", line 431, in _process_worker
    r = call_item()
  File "C:\Users\PMMCardoso\anaconda3\lib\site-packages\joblib\externals\loky\process_executor.py", line 285, in __call__
    return self.fn(*self.args, **self.kwargs)
  File "C:\Users\PMMCardoso\anaconda3\lib\site-packages\joblib\_parallel_backends.py", line 595, in __call__
    return self.func(*args, **kwargs)
  File "C:\Users\PMMCardoso\anaconda3\lib\site-packages\joblib\parallel.py", line 262, in __call__
    return [func(*args, **kwargs)
  File "C:\Users\PMMCardoso\anaconda3\lib\site-packages\joblib\parallel.py", line 262, in <listcomp>
    return [func(*args, **kwargs)
  File "C:\Users\PMMCardoso\anaconda3\lib\site-packages\sklearn\model_selection\_validation.py", line 560, in _fit_and_score
    test_scores = _score(estimator, X_test, y_test, scorer)
  File "C:\Users\PMMCardoso\anaconda3\lib\site-packages\sklearn\model_selection\_validation.py", line 607, in _score
    scores = scorer(estimator, X_test, y_test)
  File "C:\Users\PMMCardoso\anaconda3\lib\site-packages\sklearn\metrics\_scorer.py", line 87, in __call__
    score = scorer._score(cached_call, estimator,
  File "C:\Users\PMMCardoso\anaconda3\lib\site-packages\sklearn\metrics\_scorer.py", line 212, in _score
    return self._sign * self._score_func(y_true, y_pred,
  File "C:\Users\PMMCardoso\anaconda3\lib\site-packages\pycaret\internal\metrics.py", line 10, in wrapper
    return score_func(y_true, y_pred, **kwargs)
  File "C:\Users\PMMCardoso\anaconda3\lib\site-packages\sklearn\utils\validation.py", line 72, in inner_f
    return f(**kwargs)
  File "C:\Users\PMMCardoso\anaconda3\lib\site-packages\sklearn\metrics\_classification.py", line 1735, in recall_score
    _, r, _, _ = precision_recall_fscore_support(y_true, y_pred,
  File "C:\Users\PMMCardoso\anaconda3\lib\site-packages\sklearn\utils\validation.py", line 72, in inner_f
    return f(**kwargs)
  File "C:\Users\PMMCardoso\anaconda3\lib\site-packages\sklearn\metrics\_classification.py", line 1433, in precision_recall_fscore_support
    labels = _check_set_wise_labels(y_true, y_pred, average, labels,
  File "C:\Users\PMMCardoso\anaconda3\lib\site-packages\sklearn\metrics\_classification.py", line 1256, in _check_set_wise_labels
    raise ValueError("pos_label=%r is not a valid label: "
ValueError: pos_label=1 is not a valid label: array(['0.0', '1.0'], dtype='<U3')
"""

The above exception was the direct cause of the following exception:

Traceback (most recent call last):
  File "C:\Users\PMMCardoso\anaconda3\lib\site-packages\pycaret\internal\tabular.py", line 2156, in compare_models
    model, model_fit_time = create_model_supervised(
  File "C:\Users\PMMCardoso\anaconda3\lib\site-packages\pycaret\internal\tabular.py", line 3085, in create_model_supervised
    scores = cross_validate(
  File "C:\Users\PMMCardoso\anaconda3\lib\site-packages\sklearn\utils\validation.py", line 72, in inner_f
    return f(**kwargs)
  File "C:\Users\PMMCardoso\anaconda3\lib\site-packages\sklearn\model_selection\_validation.py", line 242, in cross_validate
    scores = parallel(
  File "C:\Users\PMMCardoso\anaconda3\lib\site-packages\joblib\parallel.py", line 1061, in __call__
    self.retrieve()
  File "C:\Users\PMMCardoso\anaconda3\lib\site-packages\joblib\parallel.py", line 940, in retrieve
    self._output.extend(job.get(timeout=self.timeout))
  File "C:\Users\PMMCardoso\anaconda3\lib\site-packages\joblib\_parallel_backends.py", line 542, in wrap_future_result
    return future.result(timeout=timeout)
  File "C:\Users\PMMCardoso\anaconda3\lib\concurrent\futures\_base.py", line 439, in result
    return self.__get_result()
  File "C:\Users\PMMCardoso\anaconda3\lib\concurrent\futures\_base.py", line 388, in __get_result
    raise self._exception
ValueError: pos_label=1 is not a valid label: array(['0.0', '1.0'], dtype='<U3')

2021-02-18 14:32:34,131:INFO:Initializing Ridge Classifier
2021-02-18 14:32:34,132:INFO:Total runtime is 4.80060289700826 minutes
2021-02-18 14:32:34,143:INFO:SubProcess create_model() called ==================================
2021-02-18 14:32:34,144:INFO:Initializing create_model()
2021-02-18 14:32:34,144:INFO:create_model(estimator=ridge, fold=StratifiedKFold(n_splits=10, random_state=6396, shuffle=False), round=4, cross_validation=True, predict=True, fit_kwargs={}, groups=None, refit=False, verbose=False, system=False, metrics=None, display=<pycaret.internal.Display.Display object at 0x000001D78F25C4F0>, kwargs={})
2021-02-18 14:32:34,144:INFO:Checking exceptions
2021-02-18 14:32:34,145:INFO:Importing libraries
2021-02-18 14:32:34,145:INFO:Copying training dataset
2021-02-18 14:32:34,180:INFO:Defining folds
2021-02-18 14:32:34,180:INFO:Declaring metric variables
2021-02-18 14:32:34,192:INFO:Importing untrained model
2021-02-18 14:32:34,208:INFO:Ridge Classifier Imported succesfully
2021-02-18 14:32:34,235:INFO:Starting cross validation
2021-02-18 14:32:34,236:INFO:Cross validating with StratifiedKFold(n_splits=10, random_state=6396, shuffle=False), n_jobs=-1
2021-02-18 14:32:41,439:WARNING:create_model() for ridge raised an exception or returned all 0.0, trying without fit_kwargs:
2021-02-18 14:32:41,440:WARNING:joblib.externals.loky.process_executor._RemoteTraceback: 
"""
Traceback (most recent call last):
  File "C:\Users\PMMCardoso\anaconda3\lib\site-packages\joblib\externals\loky\process_executor.py", line 431, in _process_worker
    r = call_item()
  File "C:\Users\PMMCardoso\anaconda3\lib\site-packages\joblib\externals\loky\process_executor.py", line 285, in __call__
    return self.fn(*self.args, **self.kwargs)
  File "C:\Users\PMMCardoso\anaconda3\lib\site-packages\joblib\_parallel_backends.py", line 595, in __call__
    return self.func(*args, **kwargs)
  File "C:\Users\PMMCardoso\anaconda3\lib\site-packages\joblib\parallel.py", line 262, in __call__
    return [func(*args, **kwargs)
  File "C:\Users\PMMCardoso\anaconda3\lib\site-packages\joblib\parallel.py", line 262, in <listcomp>
    return [func(*args, **kwargs)
  File "C:\Users\PMMCardoso\anaconda3\lib\site-packages\sklearn\model_selection\_validation.py", line 560, in _fit_and_score
    test_scores = _score(estimator, X_test, y_test, scorer)
  File "C:\Users\PMMCardoso\anaconda3\lib\site-packages\sklearn\model_selection\_validation.py", line 607, in _score
    scores = scorer(estimator, X_test, y_test)
  File "C:\Users\PMMCardoso\anaconda3\lib\site-packages\sklearn\metrics\_scorer.py", line 87, in __call__
    score = scorer._score(cached_call, estimator,
  File "C:\Users\PMMCardoso\anaconda3\lib\site-packages\sklearn\metrics\_scorer.py", line 212, in _score
    return self._sign * self._score_func(y_true, y_pred,
  File "C:\Users\PMMCardoso\anaconda3\lib\site-packages\pycaret\internal\metrics.py", line 10, in wrapper
    return score_func(y_true, y_pred, **kwargs)
  File "C:\Users\PMMCardoso\anaconda3\lib\site-packages\sklearn\utils\validation.py", line 72, in inner_f
    return f(**kwargs)
  File "C:\Users\PMMCardoso\anaconda3\lib\site-packages\sklearn\metrics\_classification.py", line 1735, in recall_score
    _, r, _, _ = precision_recall_fscore_support(y_true, y_pred,
  File "C:\Users\PMMCardoso\anaconda3\lib\site-packages\sklearn\utils\validation.py", line 72, in inner_f
    return f(**kwargs)
  File "C:\Users\PMMCardoso\anaconda3\lib\site-packages\sklearn\metrics\_classification.py", line 1433, in precision_recall_fscore_support
    labels = _check_set_wise_labels(y_true, y_pred, average, labels,
  File "C:\Users\PMMCardoso\anaconda3\lib\site-packages\sklearn\metrics\_classification.py", line 1256, in _check_set_wise_labels
    raise ValueError("pos_label=%r is not a valid label: "
ValueError: pos_label=1 is not a valid label: array(['0.0', '1.0'], dtype='<U3')
"""

The above exception was the direct cause of the following exception:

Traceback (most recent call last):
  File "C:\Users\PMMCardoso\anaconda3\lib\site-packages\pycaret\internal\tabular.py", line 2136, in compare_models
    model, model_fit_time = create_model_supervised(
  File "C:\Users\PMMCardoso\anaconda3\lib\site-packages\pycaret\internal\tabular.py", line 3085, in create_model_supervised
    scores = cross_validate(
  File "C:\Users\PMMCardoso\anaconda3\lib\site-packages\sklearn\utils\validation.py", line 72, in inner_f
    return f(**kwargs)
  File "C:\Users\PMMCardoso\anaconda3\lib\site-packages\sklearn\model_selection\_validation.py", line 242, in cross_validate
    scores = parallel(
  File "C:\Users\PMMCardoso\anaconda3\lib\site-packages\joblib\parallel.py", line 1061, in __call__
    self.retrieve()
  File "C:\Users\PMMCardoso\anaconda3\lib\site-packages\joblib\parallel.py", line 940, in retrieve
    self._output.extend(job.get(timeout=self.timeout))
  File "C:\Users\PMMCardoso\anaconda3\lib\site-packages\joblib\_parallel_backends.py", line 542, in wrap_future_result
    return future.result(timeout=timeout)
  File "C:\Users\PMMCardoso\anaconda3\lib\concurrent\futures\_base.py", line 439, in result
    return self.__get_result()
  File "C:\Users\PMMCardoso\anaconda3\lib\concurrent\futures\_base.py", line 388, in __get_result
    raise self._exception
ValueError: pos_label=1 is not a valid label: array(['0.0', '1.0'], dtype='<U3')

2021-02-18 14:32:41,441:INFO:Initializing create_model()
2021-02-18 14:32:41,441:INFO:create_model(estimator=ridge, fold=StratifiedKFold(n_splits=10, random_state=6396, shuffle=False), round=4, cross_validation=True, predict=True, fit_kwargs=None, groups=None, refit=False, verbose=False, system=False, metrics=None, display=<pycaret.internal.Display.Display object at 0x000001D78F25C4F0>, kwargs={})
2021-02-18 14:32:41,441:INFO:Checking exceptions
2021-02-18 14:32:41,441:INFO:Importing libraries
2021-02-18 14:32:41,441:INFO:Copying training dataset
2021-02-18 14:32:41,475:INFO:Defining folds
2021-02-18 14:32:41,475:INFO:Declaring metric variables
2021-02-18 14:32:41,490:INFO:Importing untrained model
2021-02-18 14:32:41,506:INFO:Ridge Classifier Imported succesfully
2021-02-18 14:32:41,537:INFO:Starting cross validation
2021-02-18 14:32:41,538:INFO:Cross validating with StratifiedKFold(n_splits=10, random_state=6396, shuffle=False), n_jobs=-1
2021-02-18 14:32:49,106:ERROR:create_model() for ridge raised an exception:
2021-02-18 14:32:49,108:ERROR:joblib.externals.loky.process_executor._RemoteTraceback: 
"""
Traceback (most recent call last):
  File "C:\Users\PMMCardoso\anaconda3\lib\site-packages\joblib\externals\loky\process_executor.py", line 431, in _process_worker
    r = call_item()
  File "C:\Users\PMMCardoso\anaconda3\lib\site-packages\joblib\externals\loky\process_executor.py", line 285, in __call__
    return self.fn(*self.args, **self.kwargs)
  File "C:\Users\PMMCardoso\anaconda3\lib\site-packages\joblib\_parallel_backends.py", line 595, in __call__
    return self.func(*args, **kwargs)
  File "C:\Users\PMMCardoso\anaconda3\lib\site-packages\joblib\parallel.py", line 262, in __call__
    return [func(*args, **kwargs)
  File "C:\Users\PMMCardoso\anaconda3\lib\site-packages\joblib\parallel.py", line 262, in <listcomp>
    return [func(*args, **kwargs)
  File "C:\Users\PMMCardoso\anaconda3\lib\site-packages\sklearn\model_selection\_validation.py", line 560, in _fit_and_score
    test_scores = _score(estimator, X_test, y_test, scorer)
  File "C:\Users\PMMCardoso\anaconda3\lib\site-packages\sklearn\model_selection\_validation.py", line 607, in _score
    scores = scorer(estimator, X_test, y_test)
  File "C:\Users\PMMCardoso\anaconda3\lib\site-packages\sklearn\metrics\_scorer.py", line 87, in __call__
    score = scorer._score(cached_call, estimator,
  File "C:\Users\PMMCardoso\anaconda3\lib\site-packages\sklearn\metrics\_scorer.py", line 212, in _score
    return self._sign * self._score_func(y_true, y_pred,
  File "C:\Users\PMMCardoso\anaconda3\lib\site-packages\pycaret\internal\metrics.py", line 10, in wrapper
    return score_func(y_true, y_pred, **kwargs)
  File "C:\Users\PMMCardoso\anaconda3\lib\site-packages\sklearn\utils\validation.py", line 72, in inner_f
    return f(**kwargs)
  File "C:\Users\PMMCardoso\anaconda3\lib\site-packages\sklearn\metrics\_classification.py", line 1735, in recall_score
    _, r, _, _ = precision_recall_fscore_support(y_true, y_pred,
  File "C:\Users\PMMCardoso\anaconda3\lib\site-packages\sklearn\utils\validation.py", line 72, in inner_f
    return f(**kwargs)
  File "C:\Users\PMMCardoso\anaconda3\lib\site-packages\sklearn\metrics\_classification.py", line 1433, in precision_recall_fscore_support
    labels = _check_set_wise_labels(y_true, y_pred, average, labels,
  File "C:\Users\PMMCardoso\anaconda3\lib\site-packages\sklearn\metrics\_classification.py", line 1256, in _check_set_wise_labels
    raise ValueError("pos_label=%r is not a valid label: "
ValueError: pos_label=1 is not a valid label: array(['0.0', '1.0'], dtype='<U3')
"""

The above exception was the direct cause of the following exception:

Traceback (most recent call last):
  File "C:\Users\PMMCardoso\anaconda3\lib\site-packages\pycaret\internal\tabular.py", line 2156, in compare_models
    model, model_fit_time = create_model_supervised(
  File "C:\Users\PMMCardoso\anaconda3\lib\site-packages\pycaret\internal\tabular.py", line 3085, in create_model_supervised
    scores = cross_validate(
  File "C:\Users\PMMCardoso\anaconda3\lib\site-packages\sklearn\utils\validation.py", line 72, in inner_f
    return f(**kwargs)
  File "C:\Users\PMMCardoso\anaconda3\lib\site-packages\sklearn\model_selection\_validation.py", line 242, in cross_validate
    scores = parallel(
  File "C:\Users\PMMCardoso\anaconda3\lib\site-packages\joblib\parallel.py", line 1061, in __call__
    self.retrieve()
  File "C:\Users\PMMCardoso\anaconda3\lib\site-packages\joblib\parallel.py", line 940, in retrieve
    self._output.extend(job.get(timeout=self.timeout))
  File "C:\Users\PMMCardoso\anaconda3\lib\site-packages\joblib\_parallel_backends.py", line 542, in wrap_future_result
    return future.result(timeout=timeout)
  File "C:\Users\PMMCardoso\anaconda3\lib\concurrent\futures\_base.py", line 439, in result
    return self.__get_result()
  File "C:\Users\PMMCardoso\anaconda3\lib\concurrent\futures\_base.py", line 388, in __get_result
    raise self._exception
ValueError: pos_label=1 is not a valid label: array(['0.0', '1.0'], dtype='<U3')

2021-02-18 14:32:49,109:INFO:Initializing Random Forest Classifier
2021-02-18 14:32:49,109:INFO:Total runtime is 5.05021854241689 minutes
2021-02-18 14:32:49,127:INFO:SubProcess create_model() called ==================================
2021-02-18 14:32:49,127:INFO:Initializing create_model()
2021-02-18 14:32:49,127:INFO:create_model(estimator=rf, fold=StratifiedKFold(n_splits=10, random_state=6396, shuffle=False), round=4, cross_validation=True, predict=True, fit_kwargs={}, groups=None, refit=False, verbose=False, system=False, metrics=None, display=<pycaret.internal.Display.Display object at 0x000001D78F25C4F0>, kwargs={})
2021-02-18 14:32:49,128:INFO:Checking exceptions
2021-02-18 14:32:49,128:INFO:Importing libraries
2021-02-18 14:32:49,128:INFO:Copying training dataset
2021-02-18 14:32:49,160:INFO:Defining folds
2021-02-18 14:32:49,160:INFO:Declaring metric variables
2021-02-18 14:32:49,171:INFO:Importing untrained model
2021-02-18 14:32:49,183:INFO:Random Forest Classifier Imported succesfully
2021-02-18 14:32:49,212:INFO:Starting cross validation
2021-02-18 14:32:49,213:INFO:Cross validating with StratifiedKFold(n_splits=10, random_state=6396, shuffle=False), n_jobs=-1
2021-02-18 14:33:58,462:WARNING:create_model() for rf raised an exception or returned all 0.0, trying without fit_kwargs:
2021-02-18 14:33:58,464:WARNING:joblib.externals.loky.process_executor._RemoteTraceback: 
"""
Traceback (most recent call last):
  File "C:\Users\PMMCardoso\anaconda3\lib\site-packages\joblib\externals\loky\process_executor.py", line 431, in _process_worker
    r = call_item()
  File "C:\Users\PMMCardoso\anaconda3\lib\site-packages\joblib\externals\loky\process_executor.py", line 285, in __call__
    return self.fn(*self.args, **self.kwargs)
  File "C:\Users\PMMCardoso\anaconda3\lib\site-packages\joblib\_parallel_backends.py", line 595, in __call__
    return self.func(*args, **kwargs)
  File "C:\Users\PMMCardoso\anaconda3\lib\site-packages\joblib\parallel.py", line 262, in __call__
    return [func(*args, **kwargs)
  File "C:\Users\PMMCardoso\anaconda3\lib\site-packages\joblib\parallel.py", line 262, in <listcomp>
    return [func(*args, **kwargs)
  File "C:\Users\PMMCardoso\anaconda3\lib\site-packages\sklearn\model_selection\_validation.py", line 560, in _fit_and_score
    test_scores = _score(estimator, X_test, y_test, scorer)
  File "C:\Users\PMMCardoso\anaconda3\lib\site-packages\sklearn\model_selection\_validation.py", line 607, in _score
    scores = scorer(estimator, X_test, y_test)
  File "C:\Users\PMMCardoso\anaconda3\lib\site-packages\sklearn\metrics\_scorer.py", line 87, in __call__
    score = scorer._score(cached_call, estimator,
  File "C:\Users\PMMCardoso\anaconda3\lib\site-packages\sklearn\metrics\_scorer.py", line 212, in _score
    return self._sign * self._score_func(y_true, y_pred,
  File "C:\Users\PMMCardoso\anaconda3\lib\site-packages\pycaret\internal\metrics.py", line 10, in wrapper
    return score_func(y_true, y_pred, **kwargs)
  File "C:\Users\PMMCardoso\anaconda3\lib\site-packages\sklearn\utils\validation.py", line 72, in inner_f
    return f(**kwargs)
  File "C:\Users\PMMCardoso\anaconda3\lib\site-packages\sklearn\metrics\_classification.py", line 1735, in recall_score
    _, r, _, _ = precision_recall_fscore_support(y_true, y_pred,
  File "C:\Users\PMMCardoso\anaconda3\lib\site-packages\sklearn\utils\validation.py", line 72, in inner_f
    return f(**kwargs)
  File "C:\Users\PMMCardoso\anaconda3\lib\site-packages\sklearn\metrics\_classification.py", line 1433, in precision_recall_fscore_support
    labels = _check_set_wise_labels(y_true, y_pred, average, labels,
  File "C:\Users\PMMCardoso\anaconda3\lib\site-packages\sklearn\metrics\_classification.py", line 1256, in _check_set_wise_labels
    raise ValueError("pos_label=%r is not a valid label: "
ValueError: pos_label=1 is not a valid label: array(['0.0', '1.0'], dtype='<U3')
"""

The above exception was the direct cause of the following exception:

Traceback (most recent call last):
  File "C:\Users\PMMCardoso\anaconda3\lib\site-packages\pycaret\internal\tabular.py", line 2136, in compare_models
    model, model_fit_time = create_model_supervised(
  File "C:\Users\PMMCardoso\anaconda3\lib\site-packages\pycaret\internal\tabular.py", line 3085, in create_model_supervised
    scores = cross_validate(
  File "C:\Users\PMMCardoso\anaconda3\lib\site-packages\sklearn\utils\validation.py", line 72, in inner_f
    return f(**kwargs)
  File "C:\Users\PMMCardoso\anaconda3\lib\site-packages\sklearn\model_selection\_validation.py", line 242, in cross_validate
    scores = parallel(
  File "C:\Users\PMMCardoso\anaconda3\lib\site-packages\joblib\parallel.py", line 1061, in __call__
    self.retrieve()
  File "C:\Users\PMMCardoso\anaconda3\lib\site-packages\joblib\parallel.py", line 940, in retrieve
    self._output.extend(job.get(timeout=self.timeout))
  File "C:\Users\PMMCardoso\anaconda3\lib\site-packages\joblib\_parallel_backends.py", line 542, in wrap_future_result
    return future.result(timeout=timeout)
  File "C:\Users\PMMCardoso\anaconda3\lib\concurrent\futures\_base.py", line 439, in result
    return self.__get_result()
  File "C:\Users\PMMCardoso\anaconda3\lib\concurrent\futures\_base.py", line 388, in __get_result
    raise self._exception
ValueError: pos_label=1 is not a valid label: array(['0.0', '1.0'], dtype='<U3')

2021-02-18 14:33:58,465:INFO:Initializing create_model()
2021-02-18 14:33:58,465:INFO:create_model(estimator=rf, fold=StratifiedKFold(n_splits=10, random_state=6396, shuffle=False), round=4, cross_validation=True, predict=True, fit_kwargs=None, groups=None, refit=False, verbose=False, system=False, metrics=None, display=<pycaret.internal.Display.Display object at 0x000001D78F25C4F0>, kwargs={})
2021-02-18 14:33:58,465:INFO:Checking exceptions
2021-02-18 14:33:58,465:INFO:Importing libraries
2021-02-18 14:33:58,465:INFO:Copying training dataset
2021-02-18 14:33:58,499:INFO:Defining folds
2021-02-18 14:33:58,499:INFO:Declaring metric variables
2021-02-18 14:33:58,515:INFO:Importing untrained model
2021-02-18 14:33:58,532:INFO:Random Forest Classifier Imported succesfully
2021-02-18 14:33:58,561:INFO:Starting cross validation
2021-02-18 14:33:58,562:INFO:Cross validating with StratifiedKFold(n_splits=10, random_state=6396, shuffle=False), n_jobs=-1
2021-02-18 14:35:00,256:ERROR:create_model() for rf raised an exception:
2021-02-18 14:35:00,260:ERROR:joblib.externals.loky.process_executor._RemoteTraceback: 
"""
Traceback (most recent call last):
  File "C:\Users\PMMCardoso\anaconda3\lib\site-packages\joblib\externals\loky\process_executor.py", line 431, in _process_worker
    r = call_item()
  File "C:\Users\PMMCardoso\anaconda3\lib\site-packages\joblib\externals\loky\process_executor.py", line 285, in __call__
    return self.fn(*self.args, **self.kwargs)
  File "C:\Users\PMMCardoso\anaconda3\lib\site-packages\joblib\_parallel_backends.py", line 595, in __call__
    return self.func(*args, **kwargs)
  File "C:\Users\PMMCardoso\anaconda3\lib\site-packages\joblib\parallel.py", line 262, in __call__
    return [func(*args, **kwargs)
  File "C:\Users\PMMCardoso\anaconda3\lib\site-packages\joblib\parallel.py", line 262, in <listcomp>
    return [func(*args, **kwargs)
  File "C:\Users\PMMCardoso\anaconda3\lib\site-packages\sklearn\model_selection\_validation.py", line 560, in _fit_and_score
    test_scores = _score(estimator, X_test, y_test, scorer)
  File "C:\Users\PMMCardoso\anaconda3\lib\site-packages\sklearn\model_selection\_validation.py", line 607, in _score
    scores = scorer(estimator, X_test, y_test)
  File "C:\Users\PMMCardoso\anaconda3\lib\site-packages\sklearn\metrics\_scorer.py", line 87, in __call__
    score = scorer._score(cached_call, estimator,
  File "C:\Users\PMMCardoso\anaconda3\lib\site-packages\sklearn\metrics\_scorer.py", line 212, in _score
    return self._sign * self._score_func(y_true, y_pred,
  File "C:\Users\PMMCardoso\anaconda3\lib\site-packages\pycaret\internal\metrics.py", line 10, in wrapper
    return score_func(y_true, y_pred, **kwargs)
  File "C:\Users\PMMCardoso\anaconda3\lib\site-packages\sklearn\utils\validation.py", line 72, in inner_f
    return f(**kwargs)
  File "C:\Users\PMMCardoso\anaconda3\lib\site-packages\sklearn\metrics\_classification.py", line 1735, in recall_score
    _, r, _, _ = precision_recall_fscore_support(y_true, y_pred,
  File "C:\Users\PMMCardoso\anaconda3\lib\site-packages\sklearn\utils\validation.py", line 72, in inner_f
    return f(**kwargs)
  File "C:\Users\PMMCardoso\anaconda3\lib\site-packages\sklearn\metrics\_classification.py", line 1433, in precision_recall_fscore_support
    labels = _check_set_wise_labels(y_true, y_pred, average, labels,
  File "C:\Users\PMMCardoso\anaconda3\lib\site-packages\sklearn\metrics\_classification.py", line 1256, in _check_set_wise_labels
    raise ValueError("pos_label=%r is not a valid label: "
ValueError: pos_label=1 is not a valid label: array(['0.0', '1.0'], dtype='<U3')
"""

The above exception was the direct cause of the following exception:

Traceback (most recent call last):
  File "C:\Users\PMMCardoso\anaconda3\lib\site-packages\pycaret\internal\tabular.py", line 2136, in compare_models
    model, model_fit_time = create_model_supervised(
  File "C:\Users\PMMCardoso\anaconda3\lib\site-packages\pycaret\internal\tabular.py", line 3085, in create_model_supervised
    scores = cross_validate(
  File "C:\Users\PMMCardoso\anaconda3\lib\site-packages\sklearn\utils\validation.py", line 72, in inner_f
    return f(**kwargs)
  File "C:\Users\PMMCardoso\anaconda3\lib\site-packages\sklearn\model_selection\_validation.py", line 242, in cross_validate
    scores = parallel(
  File "C:\Users\PMMCardoso\anaconda3\lib\site-packages\joblib\parallel.py", line 1061, in __call__
    self.retrieve()
  File "C:\Users\PMMCardoso\anaconda3\lib\site-packages\joblib\parallel.py", line 940, in retrieve
    self._output.extend(job.get(timeout=self.timeout))
  File "C:\Users\PMMCardoso\anaconda3\lib\site-packages\joblib\_parallel_backends.py", line 542, in wrap_future_result
    return future.result(timeout=timeout)
  File "C:\Users\PMMCardoso\anaconda3\lib\concurrent\futures\_base.py", line 439, in result
    return self.__get_result()
  File "C:\Users\PMMCardoso\anaconda3\lib\concurrent\futures\_base.py", line 388, in __get_result
    raise self._exception
ValueError: pos_label=1 is not a valid label: array(['0.0', '1.0'], dtype='<U3')

During handling of the above exception, another exception occurred:

Traceback (most recent call last):
  File "C:\Users\PMMCardoso\anaconda3\lib\site-packages\pycaret\internal\tabular.py", line 2156, in compare_models
    model, model_fit_time = create_model_supervised(
  File "C:\Users\PMMCardoso\anaconda3\lib\site-packages\pycaret\internal\tabular.py", line 3085, in create_model_supervised
    scores = cross_validate(
  File "C:\Users\PMMCardoso\anaconda3\lib\site-packages\sklearn\utils\validation.py", line 72, in inner_f
    return f(**kwargs)
  File "C:\Users\PMMCardoso\anaconda3\lib\site-packages\sklearn\model_selection\_validation.py", line 242, in cross_validate
    scores = parallel(
  File "C:\Users\PMMCardoso\anaconda3\lib\site-packages\joblib\parallel.py", line 1061, in __call__
    self.retrieve()
  File "C:\Users\PMMCardoso\anaconda3\lib\site-packages\joblib\parallel.py", line 940, in retrieve
    self._output.extend(job.get(timeout=self.timeout))
  File "C:\Users\PMMCardoso\anaconda3\lib\site-packages\joblib\_parallel_backends.py", line 542, in wrap_future_result
    return future.result(timeout=timeout)
  File "C:\Users\PMMCardoso\anaconda3\lib\concurrent\futures\_base.py", line 434, in result
    self._condition.wait(timeout)
  File "C:\Users\PMMCardoso\anaconda3\lib\threading.py", line 302, in wait
    waiter.acquire()
KeyboardInterrupt

2021-02-18 14:35:00,266:INFO:Initializing Quadratic Discriminant Analysis
2021-02-18 14:35:00,266:INFO:Total runtime is 7.236171591281891 minutes
2021-02-18 14:35:00,286:INFO:SubProcess create_model() called ==================================
2021-02-18 14:35:00,286:INFO:Initializing create_model()
2021-02-18 14:35:00,287:INFO:create_model(estimator=qda, fold=StratifiedKFold(n_splits=10, random_state=6396, shuffle=False), round=4, cross_validation=True, predict=True, fit_kwargs={}, groups=None, refit=False, verbose=False, system=False, metrics=None, display=<pycaret.internal.Display.Display object at 0x000001D78F25C4F0>, kwargs={})
2021-02-18 14:35:00,287:INFO:Checking exceptions
2021-02-18 14:35:00,287:INFO:Importing libraries
2021-02-18 14:35:00,287:INFO:Copying training dataset
2021-02-18 14:35:00,338:INFO:Defining folds
2021-02-18 14:35:00,338:INFO:Declaring metric variables
2021-02-18 14:35:00,360:INFO:Importing untrained model
2021-02-18 14:35:00,375:INFO:Quadratic Discriminant Analysis Imported succesfully
2021-02-18 14:35:00,410:INFO:Starting cross validation
2021-02-18 14:35:00,411:INFO:Cross validating with StratifiedKFold(n_splits=10, random_state=6396, shuffle=False), n_jobs=-1
2021-02-18 14:35:13,057:WARNING:create_model() for qda raised an exception or returned all 0.0, trying without fit_kwargs:
2021-02-18 14:35:13,058:WARNING:joblib.externals.loky.process_executor._RemoteTraceback: 
"""
Traceback (most recent call last):
  File "C:\Users\PMMCardoso\anaconda3\lib\site-packages\joblib\externals\loky\process_executor.py", line 431, in _process_worker
    r = call_item()
  File "C:\Users\PMMCardoso\anaconda3\lib\site-packages\joblib\externals\loky\process_executor.py", line 285, in __call__
    return self.fn(*self.args, **self.kwargs)
  File "C:\Users\PMMCardoso\anaconda3\lib\site-packages\joblib\_parallel_backends.py", line 595, in __call__
    return self.func(*args, **kwargs)
  File "C:\Users\PMMCardoso\anaconda3\lib\site-packages\joblib\parallel.py", line 262, in __call__
    return [func(*args, **kwargs)
  File "C:\Users\PMMCardoso\anaconda3\lib\site-packages\joblib\parallel.py", line 262, in <listcomp>
    return [func(*args, **kwargs)
  File "C:\Users\PMMCardoso\anaconda3\lib\site-packages\sklearn\model_selection\_validation.py", line 560, in _fit_and_score
    test_scores = _score(estimator, X_test, y_test, scorer)
  File "C:\Users\PMMCardoso\anaconda3\lib\site-packages\sklearn\model_selection\_validation.py", line 607, in _score
    scores = scorer(estimator, X_test, y_test)
  File "C:\Users\PMMCardoso\anaconda3\lib\site-packages\sklearn\metrics\_scorer.py", line 87, in __call__
    score = scorer._score(cached_call, estimator,
  File "C:\Users\PMMCardoso\anaconda3\lib\site-packages\sklearn\metrics\_scorer.py", line 212, in _score
    return self._sign * self._score_func(y_true, y_pred,
  File "C:\Users\PMMCardoso\anaconda3\lib\site-packages\pycaret\internal\metrics.py", line 10, in wrapper
    return score_func(y_true, y_pred, **kwargs)
  File "C:\Users\PMMCardoso\anaconda3\lib\site-packages\sklearn\utils\validation.py", line 72, in inner_f
    return f(**kwargs)
  File "C:\Users\PMMCardoso\anaconda3\lib\site-packages\sklearn\metrics\_classification.py", line 1735, in recall_score
    _, r, _, _ = precision_recall_fscore_support(y_true, y_pred,
  File "C:\Users\PMMCardoso\anaconda3\lib\site-packages\sklearn\utils\validation.py", line 72, in inner_f
    return f(**kwargs)
  File "C:\Users\PMMCardoso\anaconda3\lib\site-packages\sklearn\metrics\_classification.py", line 1433, in precision_recall_fscore_support
    labels = _check_set_wise_labels(y_true, y_pred, average, labels,
  File "C:\Users\PMMCardoso\anaconda3\lib\site-packages\sklearn\metrics\_classification.py", line 1256, in _check_set_wise_labels
    raise ValueError("pos_label=%r is not a valid label: "
ValueError: pos_label=1 is not a valid label: array(['0.0', '1.0'], dtype='<U3')
"""

The above exception was the direct cause of the following exception:

Traceback (most recent call last):
  File "C:\Users\PMMCardoso\anaconda3\lib\site-packages\pycaret\internal\tabular.py", line 2136, in compare_models
    model, model_fit_time = create_model_supervised(
  File "C:\Users\PMMCardoso\anaconda3\lib\site-packages\pycaret\internal\tabular.py", line 3085, in create_model_supervised
    scores = cross_validate(
  File "C:\Users\PMMCardoso\anaconda3\lib\site-packages\sklearn\utils\validation.py", line 72, in inner_f
    return f(**kwargs)
  File "C:\Users\PMMCardoso\anaconda3\lib\site-packages\sklearn\model_selection\_validation.py", line 242, in cross_validate
    scores = parallel(
  File "C:\Users\PMMCardoso\anaconda3\lib\site-packages\joblib\parallel.py", line 1061, in __call__
    self.retrieve()
  File "C:\Users\PMMCardoso\anaconda3\lib\site-packages\joblib\parallel.py", line 940, in retrieve
    self._output.extend(job.get(timeout=self.timeout))
  File "C:\Users\PMMCardoso\anaconda3\lib\site-packages\joblib\_parallel_backends.py", line 542, in wrap_future_result
    return future.result(timeout=timeout)
  File "C:\Users\PMMCardoso\anaconda3\lib\concurrent\futures\_base.py", line 439, in result
    return self.__get_result()
  File "C:\Users\PMMCardoso\anaconda3\lib\concurrent\futures\_base.py", line 388, in __get_result
    raise self._exception
ValueError: pos_label=1 is not a valid label: array(['0.0', '1.0'], dtype='<U3')

2021-02-18 14:35:13,059:INFO:Initializing create_model()
2021-02-18 14:35:13,059:INFO:create_model(estimator=qda, fold=StratifiedKFold(n_splits=10, random_state=6396, shuffle=False), round=4, cross_validation=True, predict=True, fit_kwargs=None, groups=None, refit=False, verbose=False, system=False, metrics=None, display=<pycaret.internal.Display.Display object at 0x000001D78F25C4F0>, kwargs={})
2021-02-18 14:35:13,060:INFO:Checking exceptions
2021-02-18 14:35:13,060:INFO:Importing libraries
2021-02-18 14:35:13,060:INFO:Copying training dataset
2021-02-18 14:35:13,093:INFO:Defining folds
2021-02-18 14:35:13,093:INFO:Declaring metric variables
2021-02-18 14:35:13,110:INFO:Importing untrained model
2021-02-18 14:35:13,127:INFO:Quadratic Discriminant Analysis Imported succesfully
2021-02-18 14:35:13,162:INFO:Starting cross validation
2021-02-18 14:35:13,164:INFO:Cross validating with StratifiedKFold(n_splits=10, random_state=6396, shuffle=False), n_jobs=-1
